ERROR 2021-02-13 11:07:46,142 log 16979 139748364945152 Internal Server Error: /admin/
Traceback (most recent call last):
  File "/home/krishna/Desktop/ProjectTemplates/djangoBootstrapAuthTemplate/env/lib/python3.6/site-packages/django/core/handlers/exception.py", line 47, in inner
    response = get_response(request)
  File "/home/krishna/Desktop/ProjectTemplates/djangoBootstrapAuthTemplate/env/lib/python3.6/site-packages/django/core/handlers/base.py", line 181, in _get_response
    response = wrapped_callback(request, *callback_args, **callback_kwargs)
  File "/home/krishna/Desktop/ProjectTemplates/djangoBootstrapAuthTemplate/env/lib/python3.6/site-packages/django/contrib/admin/sites.py", line 251, in wrapper
    return self.admin_view(view, cacheable)(*args, **kwargs)
  File "/home/krishna/Desktop/ProjectTemplates/djangoBootstrapAuthTemplate/env/lib/python3.6/site-packages/django/utils/decorators.py", line 130, in _wrapped_view
    response = view_func(request, *args, **kwargs)
  File "/home/krishna/Desktop/ProjectTemplates/djangoBootstrapAuthTemplate/env/lib/python3.6/site-packages/django/views/decorators/cache.py", line 44, in _wrapped_view_func
    response = view_func(request, *args, **kwargs)
  File "/home/krishna/Desktop/ProjectTemplates/djangoBootstrapAuthTemplate/env/lib/python3.6/site-packages/django/contrib/admin/sites.py", line 233, in inner
    return view(request, *args, **kwargs)
  File "/home/krishna/Desktop/ProjectTemplates/djangoBootstrapAuthTemplate/env/lib/python3.6/site-packages/django/views/decorators/cache.py", line 44, in _wrapped_view_func
    response = view_func(request, *args, **kwargs)
  File "/home/krishna/Desktop/ProjectTemplates/djangoBootstrapAuthTemplate/env/lib/python3.6/site-packages/django/contrib/admin/sites.py", line 502, in index
    app_list = self.get_app_list(request)
  File "/home/krishna/Desktop/ProjectTemplates/djangoBootstrapAuthTemplate/env/lib/python3.6/site-packages/django/contrib/admin/sites.py", line 485, in get_app_list
    app_dict = self._build_app_dict(request)
  File "/home/krishna/Desktop/ProjectTemplates/djangoBootstrapAuthTemplate/env/lib/python3.6/site-packages/django/contrib/admin/sites.py", line 434, in _build_app_dict
    perms = model_admin.get_model_perms(request)
  File "/home/krishna/Desktop/ProjectTemplates/djangoBootstrapAuthTemplate/env/lib/python3.6/site-packages/django/contrib/admin/options.py", line 659, in get_model_perms
    'add': self.has_add_permission(request),
  File "/home/krishna/Desktop/ProjectTemplates/djangoBootstrapAuthTemplate/env/lib/python3.6/site-packages/django/contrib/admin/options.py", line 481, in has_add_permission
    return request.user.has_perm("%s.%s" % (opts.app_label, codename))
TypeError: has_perm() takes 1 positional argument but 2 were given
ERROR 2021-02-13 11:07:46,142 log 16979 139748364945152 Internal Server Error: /admin/
Traceback (most recent call last):
  File "/home/krishna/Desktop/ProjectTemplates/djangoBootstrapAuthTemplate/env/lib/python3.6/site-packages/django/core/handlers/exception.py", line 47, in inner
    response = get_response(request)
  File "/home/krishna/Desktop/ProjectTemplates/djangoBootstrapAuthTemplate/env/lib/python3.6/site-packages/django/core/handlers/base.py", line 181, in _get_response
    response = wrapped_callback(request, *callback_args, **callback_kwargs)
  File "/home/krishna/Desktop/ProjectTemplates/djangoBootstrapAuthTemplate/env/lib/python3.6/site-packages/django/contrib/admin/sites.py", line 251, in wrapper
    return self.admin_view(view, cacheable)(*args, **kwargs)
  File "/home/krishna/Desktop/ProjectTemplates/djangoBootstrapAuthTemplate/env/lib/python3.6/site-packages/django/utils/decorators.py", line 130, in _wrapped_view
    response = view_func(request, *args, **kwargs)
  File "/home/krishna/Desktop/ProjectTemplates/djangoBootstrapAuthTemplate/env/lib/python3.6/site-packages/django/views/decorators/cache.py", line 44, in _wrapped_view_func
    response = view_func(request, *args, **kwargs)
  File "/home/krishna/Desktop/ProjectTemplates/djangoBootstrapAuthTemplate/env/lib/python3.6/site-packages/django/contrib/admin/sites.py", line 233, in inner
    return view(request, *args, **kwargs)
  File "/home/krishna/Desktop/ProjectTemplates/djangoBootstrapAuthTemplate/env/lib/python3.6/site-packages/django/views/decorators/cache.py", line 44, in _wrapped_view_func
    response = view_func(request, *args, **kwargs)
  File "/home/krishna/Desktop/ProjectTemplates/djangoBootstrapAuthTemplate/env/lib/python3.6/site-packages/django/contrib/admin/sites.py", line 502, in index
    app_list = self.get_app_list(request)
  File "/home/krishna/Desktop/ProjectTemplates/djangoBootstrapAuthTemplate/env/lib/python3.6/site-packages/django/contrib/admin/sites.py", line 485, in get_app_list
    app_dict = self._build_app_dict(request)
  File "/home/krishna/Desktop/ProjectTemplates/djangoBootstrapAuthTemplate/env/lib/python3.6/site-packages/django/contrib/admin/sites.py", line 434, in _build_app_dict
    perms = model_admin.get_model_perms(request)
  File "/home/krishna/Desktop/ProjectTemplates/djangoBootstrapAuthTemplate/env/lib/python3.6/site-packages/django/contrib/admin/options.py", line 659, in get_model_perms
    'add': self.has_add_permission(request),
  File "/home/krishna/Desktop/ProjectTemplates/djangoBootstrapAuthTemplate/env/lib/python3.6/site-packages/django/contrib/admin/options.py", line 481, in has_add_permission
    return request.user.has_perm("%s.%s" % (opts.app_label, codename))
TypeError: has_perm() takes 1 positional argument but 2 were given
ERROR 2021-02-13 11:07:46,206 basehttp 16979 139748364945152 "GET /admin/ HTTP/1.1" 500 123462
ERROR 2021-02-13 11:07:46,206 basehttp 16979 139748364945152 "GET /admin/ HTTP/1.1" 500 123462
ERROR 2021-02-13 13:10:31,464 log 23415 139811503904512 Internal Server Error: /account/register/
Traceback (most recent call last):
  File "/home/krishna/Desktop/ProjectTemplates/djangoBootstrapAuthTemplate/env/lib/python3.6/site-packages/django/core/handlers/exception.py", line 47, in inner
    response = get_response(request)
  File "/home/krishna/Desktop/ProjectTemplates/djangoBootstrapAuthTemplate/env/lib/python3.6/site-packages/django/core/handlers/base.py", line 181, in _get_response
    response = wrapped_callback(request, *callback_args, **callback_kwargs)
  File "/home/krishna/Desktop/ProjectTemplates/djangoBootstrapAuthTemplate/src/account/views.py", line 16, in registration_view
    account = authenticate(email, raw_password)
TypeError: authenticate() takes from 0 to 1 positional arguments but 2 were given
ERROR 2021-02-13 13:10:31,464 log 23415 139811503904512 Internal Server Error: /account/register/
Traceback (most recent call last):
  File "/home/krishna/Desktop/ProjectTemplates/djangoBootstrapAuthTemplate/env/lib/python3.6/site-packages/django/core/handlers/exception.py", line 47, in inner
    response = get_response(request)
  File "/home/krishna/Desktop/ProjectTemplates/djangoBootstrapAuthTemplate/env/lib/python3.6/site-packages/django/core/handlers/base.py", line 181, in _get_response
    response = wrapped_callback(request, *callback_args, **callback_kwargs)
  File "/home/krishna/Desktop/ProjectTemplates/djangoBootstrapAuthTemplate/src/account/views.py", line 16, in registration_view
    account = authenticate(email, raw_password)
TypeError: authenticate() takes from 0 to 1 positional arguments but 2 were given
ERROR 2021-02-13 13:10:31,530 basehttp 23415 139811503904512 "POST /account/register/ HTTP/1.1" 500 84785
ERROR 2021-02-13 13:10:31,530 basehttp 23415 139811503904512 "POST /account/register/ HTTP/1.1" 500 84785
ERROR 2021-02-13 15:21:02,371 log 30077 140535373321984 Internal Server Error: /account/login/
Traceback (most recent call last):
  File "/home/krishna/Desktop/ProjectTemplates/djangoBootstrapAuthTemplate/env/lib/python3.6/site-packages/django/core/handlers/exception.py", line 47, in inner
    response = get_response(request)
  File "/home/krishna/Desktop/ProjectTemplates/djangoBootstrapAuthTemplate/env/lib/python3.6/site-packages/django/core/handlers/base.py", line 181, in _get_response
    response = wrapped_callback(request, *callback_args, **callback_kwargs)
  File "/home/krishna/Desktop/ProjectTemplates/djangoBootstrapAuthTemplate/src/account/views.py", line 39, in login_view
    if form.is_valid():
  File "/home/krishna/Desktop/ProjectTemplates/djangoBootstrapAuthTemplate/env/lib/python3.6/site-packages/django/forms/forms.py", line 177, in is_valid
    return self.is_bound and not self.errors
  File "/home/krishna/Desktop/ProjectTemplates/djangoBootstrapAuthTemplate/env/lib/python3.6/site-packages/django/forms/forms.py", line 172, in errors
    self.full_clean()
  File "/home/krishna/Desktop/ProjectTemplates/djangoBootstrapAuthTemplate/env/lib/python3.6/site-packages/django/forms/forms.py", line 375, in full_clean
    self._clean_form()
  File "/home/krishna/Desktop/ProjectTemplates/djangoBootstrapAuthTemplate/env/lib/python3.6/site-packages/django/forms/forms.py", line 402, in _clean_form
    cleaned_data = self.clean()
  File "/home/krishna/Desktop/ProjectTemplates/djangoBootstrapAuthTemplate/src/account/forms.py", line 23, in clean
    email = self.cleaned_data['email']
KeyError: 'email'
ERROR 2021-02-13 15:21:02,371 log 30077 140535373321984 Internal Server Error: /account/login/
Traceback (most recent call last):
  File "/home/krishna/Desktop/ProjectTemplates/djangoBootstrapAuthTemplate/env/lib/python3.6/site-packages/django/core/handlers/exception.py", line 47, in inner
    response = get_response(request)
  File "/home/krishna/Desktop/ProjectTemplates/djangoBootstrapAuthTemplate/env/lib/python3.6/site-packages/django/core/handlers/base.py", line 181, in _get_response
    response = wrapped_callback(request, *callback_args, **callback_kwargs)
  File "/home/krishna/Desktop/ProjectTemplates/djangoBootstrapAuthTemplate/src/account/views.py", line 39, in login_view
    if form.is_valid():
  File "/home/krishna/Desktop/ProjectTemplates/djangoBootstrapAuthTemplate/env/lib/python3.6/site-packages/django/forms/forms.py", line 177, in is_valid
    return self.is_bound and not self.errors
  File "/home/krishna/Desktop/ProjectTemplates/djangoBootstrapAuthTemplate/env/lib/python3.6/site-packages/django/forms/forms.py", line 172, in errors
    self.full_clean()
  File "/home/krishna/Desktop/ProjectTemplates/djangoBootstrapAuthTemplate/env/lib/python3.6/site-packages/django/forms/forms.py", line 375, in full_clean
    self._clean_form()
  File "/home/krishna/Desktop/ProjectTemplates/djangoBootstrapAuthTemplate/env/lib/python3.6/site-packages/django/forms/forms.py", line 402, in _clean_form
    cleaned_data = self.clean()
  File "/home/krishna/Desktop/ProjectTemplates/djangoBootstrapAuthTemplate/src/account/forms.py", line 23, in clean
    email = self.cleaned_data['email']
KeyError: 'email'
ERROR 2021-02-13 15:21:02,416 basehttp 30077 140535373321984 "POST /account/login/ HTTP/1.1" 500 101916
ERROR 2021-02-13 15:21:02,416 basehttp 30077 140535373321984 "POST /account/login/ HTTP/1.1" 500 101916
ERROR 2021-02-13 16:32:59,152 log 1878 140714939774720 Internal Server Error: /account/login/
Traceback (most recent call last):
  File "/home/krishna/Desktop/ProjectTemplates/djangoBootstrapAuthTemplate/env/lib/python3.6/site-packages/django/template/backends/django.py", line 61, in render
    return self.template.render(context)
  File "/home/krishna/Desktop/ProjectTemplates/djangoBootstrapAuthTemplate/env/lib/python3.6/site-packages/django/template/base.py", line 170, in render
    return self._render(context)
  File "/home/krishna/Desktop/ProjectTemplates/djangoBootstrapAuthTemplate/env/lib/python3.6/site-packages/django/test/utils.py", line 96, in instrumented_test_render
    return self.nodelist.render(context)
  File "/home/krishna/Desktop/ProjectTemplates/djangoBootstrapAuthTemplate/env/lib/python3.6/site-packages/django/template/base.py", line 938, in render
    bit = node.render_annotated(context)
  File "/home/krishna/Desktop/ProjectTemplates/djangoBootstrapAuthTemplate/env/lib/python3.6/site-packages/django/template/base.py", line 905, in render_annotated
    return self.render(context)
  File "/home/krishna/Desktop/ProjectTemplates/djangoBootstrapAuthTemplate/env/lib/python3.6/site-packages/django/template/loader_tags.py", line 127, in render
    compiled_parent = self.get_parent(context)
  File "/home/krishna/Desktop/ProjectTemplates/djangoBootstrapAuthTemplate/env/lib/python3.6/site-packages/django/template/loader_tags.py", line 124, in get_parent
    return self.find_template(parent, context)
  File "/home/krishna/Desktop/ProjectTemplates/djangoBootstrapAuthTemplate/env/lib/python3.6/site-packages/django/template/loader_tags.py", line 104, in find_template
    template_name, skip=history,
  File "/home/krishna/Desktop/ProjectTemplates/djangoBootstrapAuthTemplate/env/lib/python3.6/site-packages/django/template/engine.py", line 129, in find_template
    raise TemplateDoesNotExist(name, tried=tried)
django.template.exceptions.TemplateDoesNotExist: base.html

The above exception was the direct cause of the following exception:

Traceback (most recent call last):
  File "/home/krishna/Desktop/ProjectTemplates/djangoBootstrapAuthTemplate/env/lib/python3.6/site-packages/django/core/handlers/exception.py", line 47, in inner
    response = get_response(request)
  File "/home/krishna/Desktop/ProjectTemplates/djangoBootstrapAuthTemplate/env/lib/python3.6/site-packages/django/core/handlers/base.py", line 181, in _get_response
    response = wrapped_callback(request, *callback_args, **callback_kwargs)
  File "/home/krishna/Desktop/ProjectTemplates/djangoBootstrapAuthTemplate/src/account/views.py", line 55, in login_view
    return render(request, 'account/login.html', context)
  File "/home/krishna/Desktop/ProjectTemplates/djangoBootstrapAuthTemplate/env/lib/python3.6/site-packages/django/shortcuts.py", line 19, in render
    content = loader.render_to_string(template_name, context, request, using=using)
  File "/home/krishna/Desktop/ProjectTemplates/djangoBootstrapAuthTemplate/env/lib/python3.6/site-packages/django/template/loader.py", line 62, in render_to_string
    return template.render(context, request)
  File "/home/krishna/Desktop/ProjectTemplates/djangoBootstrapAuthTemplate/env/lib/python3.6/site-packages/django/template/backends/django.py", line 63, in render
    reraise(exc, self.backend)
  File "/home/krishna/Desktop/ProjectTemplates/djangoBootstrapAuthTemplate/env/lib/python3.6/site-packages/django/template/backends/django.py", line 84, in reraise
    raise new from exc
django.template.exceptions.TemplateDoesNotExist: base.html
ERROR 2021-02-13 16:32:59,152 log 1878 140714939774720 Internal Server Error: /account/login/
Traceback (most recent call last):
  File "/home/krishna/Desktop/ProjectTemplates/djangoBootstrapAuthTemplate/env/lib/python3.6/site-packages/django/template/backends/django.py", line 61, in render
    return self.template.render(context)
  File "/home/krishna/Desktop/ProjectTemplates/djangoBootstrapAuthTemplate/env/lib/python3.6/site-packages/django/template/base.py", line 170, in render
    return self._render(context)
  File "/home/krishna/Desktop/ProjectTemplates/djangoBootstrapAuthTemplate/env/lib/python3.6/site-packages/django/test/utils.py", line 96, in instrumented_test_render
    return self.nodelist.render(context)
  File "/home/krishna/Desktop/ProjectTemplates/djangoBootstrapAuthTemplate/env/lib/python3.6/site-packages/django/template/base.py", line 938, in render
    bit = node.render_annotated(context)
  File "/home/krishna/Desktop/ProjectTemplates/djangoBootstrapAuthTemplate/env/lib/python3.6/site-packages/django/template/base.py", line 905, in render_annotated
    return self.render(context)
  File "/home/krishna/Desktop/ProjectTemplates/djangoBootstrapAuthTemplate/env/lib/python3.6/site-packages/django/template/loader_tags.py", line 127, in render
    compiled_parent = self.get_parent(context)
  File "/home/krishna/Desktop/ProjectTemplates/djangoBootstrapAuthTemplate/env/lib/python3.6/site-packages/django/template/loader_tags.py", line 124, in get_parent
    return self.find_template(parent, context)
  File "/home/krishna/Desktop/ProjectTemplates/djangoBootstrapAuthTemplate/env/lib/python3.6/site-packages/django/template/loader_tags.py", line 104, in find_template
    template_name, skip=history,
  File "/home/krishna/Desktop/ProjectTemplates/djangoBootstrapAuthTemplate/env/lib/python3.6/site-packages/django/template/engine.py", line 129, in find_template
    raise TemplateDoesNotExist(name, tried=tried)
django.template.exceptions.TemplateDoesNotExist: base.html

The above exception was the direct cause of the following exception:

Traceback (most recent call last):
  File "/home/krishna/Desktop/ProjectTemplates/djangoBootstrapAuthTemplate/env/lib/python3.6/site-packages/django/core/handlers/exception.py", line 47, in inner
    response = get_response(request)
  File "/home/krishna/Desktop/ProjectTemplates/djangoBootstrapAuthTemplate/env/lib/python3.6/site-packages/django/core/handlers/base.py", line 181, in _get_response
    response = wrapped_callback(request, *callback_args, **callback_kwargs)
  File "/home/krishna/Desktop/ProjectTemplates/djangoBootstrapAuthTemplate/src/account/views.py", line 55, in login_view
    return render(request, 'account/login.html', context)
  File "/home/krishna/Desktop/ProjectTemplates/djangoBootstrapAuthTemplate/env/lib/python3.6/site-packages/django/shortcuts.py", line 19, in render
    content = loader.render_to_string(template_name, context, request, using=using)
  File "/home/krishna/Desktop/ProjectTemplates/djangoBootstrapAuthTemplate/env/lib/python3.6/site-packages/django/template/loader.py", line 62, in render_to_string
    return template.render(context, request)
  File "/home/krishna/Desktop/ProjectTemplates/djangoBootstrapAuthTemplate/env/lib/python3.6/site-packages/django/template/backends/django.py", line 63, in render
    reraise(exc, self.backend)
  File "/home/krishna/Desktop/ProjectTemplates/djangoBootstrapAuthTemplate/env/lib/python3.6/site-packages/django/template/backends/django.py", line 84, in reraise
    raise new from exc
django.template.exceptions.TemplateDoesNotExist: base.html
ERROR 2021-02-13 16:32:59,179 basehttp 1878 140714939774720 "GET /account/login/ HTTP/1.1" 500 144983
ERROR 2021-02-13 16:32:59,179 basehttp 1878 140714939774720 "GET /account/login/ HTTP/1.1" 500 144983
ERROR 2021-02-13 16:42:17,564 log 1878 140714939774720 Internal Server Error: /account/account/
Traceback (most recent call last):
  File "/home/krishna/Desktop/ProjectTemplates/djangoBootstrapAuthTemplate/env/lib/python3.6/site-packages/django/template/backends/django.py", line 61, in render
    return self.template.render(context)
  File "/home/krishna/Desktop/ProjectTemplates/djangoBootstrapAuthTemplate/env/lib/python3.6/site-packages/django/template/base.py", line 170, in render
    return self._render(context)
  File "/home/krishna/Desktop/ProjectTemplates/djangoBootstrapAuthTemplate/env/lib/python3.6/site-packages/django/test/utils.py", line 96, in instrumented_test_render
    return self.nodelist.render(context)
  File "/home/krishna/Desktop/ProjectTemplates/djangoBootstrapAuthTemplate/env/lib/python3.6/site-packages/django/template/base.py", line 938, in render
    bit = node.render_annotated(context)
  File "/home/krishna/Desktop/ProjectTemplates/djangoBootstrapAuthTemplate/env/lib/python3.6/site-packages/django/template/base.py", line 905, in render_annotated
    return self.render(context)
  File "/home/krishna/Desktop/ProjectTemplates/djangoBootstrapAuthTemplate/env/lib/python3.6/site-packages/django/template/loader_tags.py", line 127, in render
    compiled_parent = self.get_parent(context)
  File "/home/krishna/Desktop/ProjectTemplates/djangoBootstrapAuthTemplate/env/lib/python3.6/site-packages/django/template/loader_tags.py", line 124, in get_parent
    return self.find_template(parent, context)
  File "/home/krishna/Desktop/ProjectTemplates/djangoBootstrapAuthTemplate/env/lib/python3.6/site-packages/django/template/loader_tags.py", line 104, in find_template
    template_name, skip=history,
  File "/home/krishna/Desktop/ProjectTemplates/djangoBootstrapAuthTemplate/env/lib/python3.6/site-packages/django/template/engine.py", line 129, in find_template
    raise TemplateDoesNotExist(name, tried=tried)
django.template.exceptions.TemplateDoesNotExist: base.html

The above exception was the direct cause of the following exception:

Traceback (most recent call last):
  File "/home/krishna/Desktop/ProjectTemplates/djangoBootstrapAuthTemplate/env/lib/python3.6/site-packages/django/core/handlers/exception.py", line 47, in inner
    response = get_response(request)
  File "/home/krishna/Desktop/ProjectTemplates/djangoBootstrapAuthTemplate/env/lib/python3.6/site-packages/django/core/handlers/base.py", line 181, in _get_response
    response = wrapped_callback(request, *callback_args, **callback_kwargs)
  File "/home/krishna/Desktop/ProjectTemplates/djangoBootstrapAuthTemplate/src/account/views.py", line 77, in account_view
    return render(request, 'account/account.html', context)
  File "/home/krishna/Desktop/ProjectTemplates/djangoBootstrapAuthTemplate/env/lib/python3.6/site-packages/django/shortcuts.py", line 19, in render
    content = loader.render_to_string(template_name, context, request, using=using)
  File "/home/krishna/Desktop/ProjectTemplates/djangoBootstrapAuthTemplate/env/lib/python3.6/site-packages/django/template/loader.py", line 62, in render_to_string
    return template.render(context, request)
  File "/home/krishna/Desktop/ProjectTemplates/djangoBootstrapAuthTemplate/env/lib/python3.6/site-packages/django/template/backends/django.py", line 63, in render
    reraise(exc, self.backend)
  File "/home/krishna/Desktop/ProjectTemplates/djangoBootstrapAuthTemplate/env/lib/python3.6/site-packages/django/template/backends/django.py", line 84, in reraise
    raise new from exc
django.template.exceptions.TemplateDoesNotExist: base.html
ERROR 2021-02-13 16:42:17,564 log 1878 140714939774720 Internal Server Error: /account/account/
Traceback (most recent call last):
  File "/home/krishna/Desktop/ProjectTemplates/djangoBootstrapAuthTemplate/env/lib/python3.6/site-packages/django/template/backends/django.py", line 61, in render
    return self.template.render(context)
  File "/home/krishna/Desktop/ProjectTemplates/djangoBootstrapAuthTemplate/env/lib/python3.6/site-packages/django/template/base.py", line 170, in render
    return self._render(context)
  File "/home/krishna/Desktop/ProjectTemplates/djangoBootstrapAuthTemplate/env/lib/python3.6/site-packages/django/test/utils.py", line 96, in instrumented_test_render
    return self.nodelist.render(context)
  File "/home/krishna/Desktop/ProjectTemplates/djangoBootstrapAuthTemplate/env/lib/python3.6/site-packages/django/template/base.py", line 938, in render
    bit = node.render_annotated(context)
  File "/home/krishna/Desktop/ProjectTemplates/djangoBootstrapAuthTemplate/env/lib/python3.6/site-packages/django/template/base.py", line 905, in render_annotated
    return self.render(context)
  File "/home/krishna/Desktop/ProjectTemplates/djangoBootstrapAuthTemplate/env/lib/python3.6/site-packages/django/template/loader_tags.py", line 127, in render
    compiled_parent = self.get_parent(context)
  File "/home/krishna/Desktop/ProjectTemplates/djangoBootstrapAuthTemplate/env/lib/python3.6/site-packages/django/template/loader_tags.py", line 124, in get_parent
    return self.find_template(parent, context)
  File "/home/krishna/Desktop/ProjectTemplates/djangoBootstrapAuthTemplate/env/lib/python3.6/site-packages/django/template/loader_tags.py", line 104, in find_template
    template_name, skip=history,
  File "/home/krishna/Desktop/ProjectTemplates/djangoBootstrapAuthTemplate/env/lib/python3.6/site-packages/django/template/engine.py", line 129, in find_template
    raise TemplateDoesNotExist(name, tried=tried)
django.template.exceptions.TemplateDoesNotExist: base.html

The above exception was the direct cause of the following exception:

Traceback (most recent call last):
  File "/home/krishna/Desktop/ProjectTemplates/djangoBootstrapAuthTemplate/env/lib/python3.6/site-packages/django/core/handlers/exception.py", line 47, in inner
    response = get_response(request)
  File "/home/krishna/Desktop/ProjectTemplates/djangoBootstrapAuthTemplate/env/lib/python3.6/site-packages/django/core/handlers/base.py", line 181, in _get_response
    response = wrapped_callback(request, *callback_args, **callback_kwargs)
  File "/home/krishna/Desktop/ProjectTemplates/djangoBootstrapAuthTemplate/src/account/views.py", line 77, in account_view
    return render(request, 'account/account.html', context)
  File "/home/krishna/Desktop/ProjectTemplates/djangoBootstrapAuthTemplate/env/lib/python3.6/site-packages/django/shortcuts.py", line 19, in render
    content = loader.render_to_string(template_name, context, request, using=using)
  File "/home/krishna/Desktop/ProjectTemplates/djangoBootstrapAuthTemplate/env/lib/python3.6/site-packages/django/template/loader.py", line 62, in render_to_string
    return template.render(context, request)
  File "/home/krishna/Desktop/ProjectTemplates/djangoBootstrapAuthTemplate/env/lib/python3.6/site-packages/django/template/backends/django.py", line 63, in render
    reraise(exc, self.backend)
  File "/home/krishna/Desktop/ProjectTemplates/djangoBootstrapAuthTemplate/env/lib/python3.6/site-packages/django/template/backends/django.py", line 84, in reraise
    raise new from exc
django.template.exceptions.TemplateDoesNotExist: base.html
ERROR 2021-02-13 16:42:17,610 basehttp 1878 140714939774720 "GET /account/account/ HTTP/1.1" 500 144155
ERROR 2021-02-13 16:42:17,610 basehttp 1878 140714939774720 "GET /account/account/ HTTP/1.1" 500 144155
ERROR 2021-02-13 22:33:13,615 log 10819 140640061241088 Internal Server Error: /account/register/
Traceback (most recent call last):
  File "/home/krishna/Desktop/ProjectTemplates/djangoBootstrapAuthTemplate/env/lib/python3.6/site-packages/django/core/handlers/exception.py", line 47, in inner
    response = get_response(request)
  File "/home/krishna/Desktop/ProjectTemplates/djangoBootstrapAuthTemplate/env/lib/python3.6/site-packages/django/core/handlers/base.py", line 181, in _get_response
    response = wrapped_callback(request, *callback_args, **callback_kwargs)
  File "/home/krishna/Desktop/ProjectTemplates/djangoBootstrapAuthTemplate/src/account/views.py", line 23, in registration_view
    login(request, account)
  File "/home/krishna/Desktop/ProjectTemplates/djangoBootstrapAuthTemplate/env/lib/python3.6/site-packages/django/contrib/auth/__init__.py", line 126, in login
    request.session[SESSION_KEY] = user._meta.pk.value_to_string(user)
  File "/home/krishna/Desktop/ProjectTemplates/djangoBootstrapAuthTemplate/env/lib/python3.6/site-packages/django/utils/functional.py", line 241, in inner
    return func(self._wrapped, *args)
AttributeError: 'AnonymousUser' object has no attribute '_meta'
ERROR 2021-02-13 22:33:13,615 log 10819 140640061241088 Internal Server Error: /account/register/
Traceback (most recent call last):
  File "/home/krishna/Desktop/ProjectTemplates/djangoBootstrapAuthTemplate/env/lib/python3.6/site-packages/django/core/handlers/exception.py", line 47, in inner
    response = get_response(request)
  File "/home/krishna/Desktop/ProjectTemplates/djangoBootstrapAuthTemplate/env/lib/python3.6/site-packages/django/core/handlers/base.py", line 181, in _get_response
    response = wrapped_callback(request, *callback_args, **callback_kwargs)
  File "/home/krishna/Desktop/ProjectTemplates/djangoBootstrapAuthTemplate/src/account/views.py", line 23, in registration_view
    login(request, account)
  File "/home/krishna/Desktop/ProjectTemplates/djangoBootstrapAuthTemplate/env/lib/python3.6/site-packages/django/contrib/auth/__init__.py", line 126, in login
    request.session[SESSION_KEY] = user._meta.pk.value_to_string(user)
  File "/home/krishna/Desktop/ProjectTemplates/djangoBootstrapAuthTemplate/env/lib/python3.6/site-packages/django/utils/functional.py", line 241, in inner
    return func(self._wrapped, *args)
AttributeError: 'AnonymousUser' object has no attribute '_meta'
ERROR 2021-02-13 22:33:13,678 basehttp 10819 140640061241088 "POST /account/register/ HTTP/1.1" 500 93920
ERROR 2021-02-13 22:33:13,678 basehttp 10819 140640061241088 "POST /account/register/ HTTP/1.1" 500 93920
ERROR 2021-02-13 22:41:30,340 log 15710 140478165432064 Internal Server Error: /account/register/
Traceback (most recent call last):
  File "/home/krishna/Desktop/ProjectTemplates/djangoBootstrapAuthTemplate/env/lib/python3.6/site-packages/django/core/handlers/exception.py", line 47, in inner
    response = get_response(request)
  File "/home/krishna/Desktop/ProjectTemplates/djangoBootstrapAuthTemplate/env/lib/python3.6/site-packages/django/core/handlers/base.py", line 181, in _get_response
    response = wrapped_callback(request, *callback_args, **callback_kwargs)
  File "/home/krishna/Desktop/ProjectTemplates/djangoBootstrapAuthTemplate/src/account/views.py", line 23, in registration_view
    login(request, account)
  File "/home/krishna/Desktop/ProjectTemplates/djangoBootstrapAuthTemplate/env/lib/python3.6/site-packages/django/contrib/auth/__init__.py", line 126, in login
    request.session[SESSION_KEY] = user._meta.pk.value_to_string(user)
  File "/home/krishna/Desktop/ProjectTemplates/djangoBootstrapAuthTemplate/env/lib/python3.6/site-packages/django/utils/functional.py", line 241, in inner
    return func(self._wrapped, *args)
AttributeError: 'AnonymousUser' object has no attribute '_meta'
ERROR 2021-02-13 22:41:30,340 log 15710 140478165432064 Internal Server Error: /account/register/
Traceback (most recent call last):
  File "/home/krishna/Desktop/ProjectTemplates/djangoBootstrapAuthTemplate/env/lib/python3.6/site-packages/django/core/handlers/exception.py", line 47, in inner
    response = get_response(request)
  File "/home/krishna/Desktop/ProjectTemplates/djangoBootstrapAuthTemplate/env/lib/python3.6/site-packages/django/core/handlers/base.py", line 181, in _get_response
    response = wrapped_callback(request, *callback_args, **callback_kwargs)
  File "/home/krishna/Desktop/ProjectTemplates/djangoBootstrapAuthTemplate/src/account/views.py", line 23, in registration_view
    login(request, account)
  File "/home/krishna/Desktop/ProjectTemplates/djangoBootstrapAuthTemplate/env/lib/python3.6/site-packages/django/contrib/auth/__init__.py", line 126, in login
    request.session[SESSION_KEY] = user._meta.pk.value_to_string(user)
  File "/home/krishna/Desktop/ProjectTemplates/djangoBootstrapAuthTemplate/env/lib/python3.6/site-packages/django/utils/functional.py", line 241, in inner
    return func(self._wrapped, *args)
AttributeError: 'AnonymousUser' object has no attribute '_meta'
ERROR 2021-02-13 22:41:30,407 basehttp 15710 140478165432064 "POST /account/register/ HTTP/1.1" 500 93932
ERROR 2021-02-13 22:41:30,407 basehttp 15710 140478165432064 "POST /account/register/ HTTP/1.1" 500 93932
ERROR 2021-02-16 13:05:17,584 log 19914 140489072953088 Internal Server Error: /account/password_reset/
Traceback (most recent call last):
  File "/home/krishna/Desktop/ProjectTemplates/djangoBootstrapAuthTemplate/env/lib/python3.6/site-packages/django/core/handlers/exception.py", line 47, in inner
    response = get_response(request)
  File "/home/krishna/Desktop/ProjectTemplates/djangoBootstrapAuthTemplate/env/lib/python3.6/site-packages/django/core/handlers/base.py", line 204, in _get_response
    response = response.render()
  File "/home/krishna/Desktop/ProjectTemplates/djangoBootstrapAuthTemplate/env/lib/python3.6/site-packages/django/template/response.py", line 105, in render
    self.content = self.rendered_content
  File "/home/krishna/Desktop/ProjectTemplates/djangoBootstrapAuthTemplate/env/lib/python3.6/site-packages/django/template/response.py", line 81, in rendered_content
    template = self.resolve_template(self.template_name)
  File "/home/krishna/Desktop/ProjectTemplates/djangoBootstrapAuthTemplate/env/lib/python3.6/site-packages/django/template/response.py", line 63, in resolve_template
    return select_template(template, using=self.using)
  File "/home/krishna/Desktop/ProjectTemplates/djangoBootstrapAuthTemplate/env/lib/python3.6/site-packages/django/template/loader.py", line 47, in select_template
    raise TemplateDoesNotExist(', '.join(template_name_list), chain=chain)
django.template.exceptions.TemplateDoesNotExist: account/password_reset_view.html
ERROR 2021-02-16 13:05:17,584 log 19914 140489072953088 Internal Server Error: /account/password_reset/
Traceback (most recent call last):
  File "/home/krishna/Desktop/ProjectTemplates/djangoBootstrapAuthTemplate/env/lib/python3.6/site-packages/django/core/handlers/exception.py", line 47, in inner
    response = get_response(request)
  File "/home/krishna/Desktop/ProjectTemplates/djangoBootstrapAuthTemplate/env/lib/python3.6/site-packages/django/core/handlers/base.py", line 204, in _get_response
    response = response.render()
  File "/home/krishna/Desktop/ProjectTemplates/djangoBootstrapAuthTemplate/env/lib/python3.6/site-packages/django/template/response.py", line 105, in render
    self.content = self.rendered_content
  File "/home/krishna/Desktop/ProjectTemplates/djangoBootstrapAuthTemplate/env/lib/python3.6/site-packages/django/template/response.py", line 81, in rendered_content
    template = self.resolve_template(self.template_name)
  File "/home/krishna/Desktop/ProjectTemplates/djangoBootstrapAuthTemplate/env/lib/python3.6/site-packages/django/template/response.py", line 63, in resolve_template
    return select_template(template, using=self.using)
  File "/home/krishna/Desktop/ProjectTemplates/djangoBootstrapAuthTemplate/env/lib/python3.6/site-packages/django/template/loader.py", line 47, in select_template
    raise TemplateDoesNotExist(', '.join(template_name_list), chain=chain)
django.template.exceptions.TemplateDoesNotExist: account/password_reset_view.html
ERROR 2021-02-16 13:05:17,668 basehttp 19914 140489072953088 "GET /account/password_reset/ HTTP/1.1" 500 98287
ERROR 2021-02-16 13:05:17,668 basehttp 19914 140489072953088 "GET /account/password_reset/ HTTP/1.1" 500 98287
ERROR 2021-02-16 15:51:07,481 log 31365 139809089976064 Internal Server Error: /account/register/
Traceback (most recent call last):
  File "/home/krishna/Desktop/ProjectTemplates/djangoBootstrapAuthTemplate/env/lib/python3.6/site-packages/django/utils/module_loading.py", line 13, in import_string
    module_path, class_name = dotted_path.rsplit('.', 1)
ValueError: not enough values to unpack (expected 2, got 1)

The above exception was the direct cause of the following exception:

Traceback (most recent call last):
  File "/home/krishna/Desktop/ProjectTemplates/djangoBootstrapAuthTemplate/env/lib/python3.6/site-packages/django/core/handlers/exception.py", line 47, in inner
    response = get_response(request)
  File "/home/krishna/Desktop/ProjectTemplates/djangoBootstrapAuthTemplate/env/lib/python3.6/site-packages/django/core/handlers/base.py", line 181, in _get_response
    response = wrapped_callback(request, *callback_args, **callback_kwargs)
  File "/home/krishna/Desktop/ProjectTemplates/djangoBootstrapAuthTemplate/src/account/views.py", line 48, in registration_view
    email.send()
  File "/home/krishna/Desktop/ProjectTemplates/djangoBootstrapAuthTemplate/env/lib/python3.6/site-packages/django/core/mail/message.py", line 284, in send
    return self.get_connection(fail_silently).send_messages([self])
  File "/home/krishna/Desktop/ProjectTemplates/djangoBootstrapAuthTemplate/env/lib/python3.6/site-packages/django/core/mail/message.py", line 241, in get_connection
    self.connection = get_connection(fail_silently=fail_silently)
  File "/home/krishna/Desktop/ProjectTemplates/djangoBootstrapAuthTemplate/env/lib/python3.6/site-packages/django/core/mail/__init__.py", line 34, in get_connection
    klass = import_string(backend or settings.EMAIL_BACKEND)
  File "/home/krishna/Desktop/ProjectTemplates/djangoBootstrapAuthTemplate/env/lib/python3.6/site-packages/django/utils/module_loading.py", line 15, in import_string
    raise ImportError("%s doesn't look like a module path" % dotted_path) from err
ImportError:  doesn't look like a module path
ERROR 2021-02-16 15:51:07,481 log 31365 139809089976064 Internal Server Error: /account/register/
Traceback (most recent call last):
  File "/home/krishna/Desktop/ProjectTemplates/djangoBootstrapAuthTemplate/env/lib/python3.6/site-packages/django/utils/module_loading.py", line 13, in import_string
    module_path, class_name = dotted_path.rsplit('.', 1)
ValueError: not enough values to unpack (expected 2, got 1)

The above exception was the direct cause of the following exception:

Traceback (most recent call last):
  File "/home/krishna/Desktop/ProjectTemplates/djangoBootstrapAuthTemplate/env/lib/python3.6/site-packages/django/core/handlers/exception.py", line 47, in inner
    response = get_response(request)
  File "/home/krishna/Desktop/ProjectTemplates/djangoBootstrapAuthTemplate/env/lib/python3.6/site-packages/django/core/handlers/base.py", line 181, in _get_response
    response = wrapped_callback(request, *callback_args, **callback_kwargs)
  File "/home/krishna/Desktop/ProjectTemplates/djangoBootstrapAuthTemplate/src/account/views.py", line 48, in registration_view
    email.send()
  File "/home/krishna/Desktop/ProjectTemplates/djangoBootstrapAuthTemplate/env/lib/python3.6/site-packages/django/core/mail/message.py", line 284, in send
    return self.get_connection(fail_silently).send_messages([self])
  File "/home/krishna/Desktop/ProjectTemplates/djangoBootstrapAuthTemplate/env/lib/python3.6/site-packages/django/core/mail/message.py", line 241, in get_connection
    self.connection = get_connection(fail_silently=fail_silently)
  File "/home/krishna/Desktop/ProjectTemplates/djangoBootstrapAuthTemplate/env/lib/python3.6/site-packages/django/core/mail/__init__.py", line 34, in get_connection
    klass = import_string(backend or settings.EMAIL_BACKEND)
  File "/home/krishna/Desktop/ProjectTemplates/djangoBootstrapAuthTemplate/env/lib/python3.6/site-packages/django/utils/module_loading.py", line 15, in import_string
    raise ImportError("%s doesn't look like a module path" % dotted_path) from err
ImportError:  doesn't look like a module path
ERROR 2021-02-16 15:51:07,541 basehttp 31365 139809089976064 "POST /account/register/ HTTP/1.1" 500 106297
ERROR 2021-02-16 15:51:07,541 basehttp 31365 139809089976064 "POST /account/register/ HTTP/1.1" 500 106297
ERROR 2021-02-16 15:58:40,403 log 31956 139680805078784 Internal Server Error: /account/activate/OA/ai670c-87e87f612c04367ca77e661b3b17b1d8/
Traceback (most recent call last):
  File "/home/krishna/Desktop/ProjectTemplates/djangoBootstrapAuthTemplate/env/lib/python3.6/site-packages/django/core/handlers/exception.py", line 47, in inner
    response = get_response(request)
  File "/home/krishna/Desktop/ProjectTemplates/djangoBootstrapAuthTemplate/env/lib/python3.6/site-packages/django/core/handlers/base.py", line 181, in _get_response
    response = wrapped_callback(request, *callback_args, **callback_kwargs)
  File "/home/krishna/Desktop/ProjectTemplates/djangoBootstrapAuthTemplate/src/account/views.py", line 122, in activate
    user = User.objects.get(pk=uid)
  File "/home/krishna/Desktop/ProjectTemplates/djangoBootstrapAuthTemplate/env/lib/python3.6/site-packages/django/db/models/manager.py", line 191, in __get__
    cls._meta.swapped,
AttributeError: Manager isn't available; 'auth.User' has been swapped for 'account.Account'
ERROR 2021-02-16 15:58:40,403 log 31956 139680805078784 Internal Server Error: /account/activate/OA/ai670c-87e87f612c04367ca77e661b3b17b1d8/
Traceback (most recent call last):
  File "/home/krishna/Desktop/ProjectTemplates/djangoBootstrapAuthTemplate/env/lib/python3.6/site-packages/django/core/handlers/exception.py", line 47, in inner
    response = get_response(request)
  File "/home/krishna/Desktop/ProjectTemplates/djangoBootstrapAuthTemplate/env/lib/python3.6/site-packages/django/core/handlers/base.py", line 181, in _get_response
    response = wrapped_callback(request, *callback_args, **callback_kwargs)
  File "/home/krishna/Desktop/ProjectTemplates/djangoBootstrapAuthTemplate/src/account/views.py", line 122, in activate
    user = User.objects.get(pk=uid)
  File "/home/krishna/Desktop/ProjectTemplates/djangoBootstrapAuthTemplate/env/lib/python3.6/site-packages/django/db/models/manager.py", line 191, in __get__
    cls._meta.swapped,
AttributeError: Manager isn't available; 'auth.User' has been swapped for 'account.Account'
ERROR 2021-02-16 15:58:40,455 basehttp 31956 139680805078784 "GET /account/activate/OA/ai670c-87e87f612c04367ca77e661b3b17b1d8/ HTTP/1.1" 500 87714
ERROR 2021-02-16 15:58:40,455 basehttp 31956 139680805078784 "GET /account/activate/OA/ai670c-87e87f612c04367ca77e661b3b17b1d8/ HTTP/1.1" 500 87714
ERROR 2021-02-16 15:59:47,398 log 31956 139680817501952 Internal Server Error: /account/activate/OQ/ai6739-7701f30b58ca5a7e6266523e8f7e1150/
Traceback (most recent call last):
  File "/home/krishna/Desktop/ProjectTemplates/djangoBootstrapAuthTemplate/env/lib/python3.6/site-packages/django/core/handlers/exception.py", line 47, in inner
    response = get_response(request)
  File "/home/krishna/Desktop/ProjectTemplates/djangoBootstrapAuthTemplate/env/lib/python3.6/site-packages/django/core/handlers/base.py", line 181, in _get_response
    response = wrapped_callback(request, *callback_args, **callback_kwargs)
  File "/home/krishna/Desktop/ProjectTemplates/djangoBootstrapAuthTemplate/src/account/views.py", line 122, in activate
    user = User.objects.get(pk=uid)
  File "/home/krishna/Desktop/ProjectTemplates/djangoBootstrapAuthTemplate/env/lib/python3.6/site-packages/django/db/models/manager.py", line 191, in __get__
    cls._meta.swapped,
AttributeError: Manager isn't available; 'auth.User' has been swapped for 'account.Account'
ERROR 2021-02-16 15:59:47,398 log 31956 139680817501952 Internal Server Error: /account/activate/OQ/ai6739-7701f30b58ca5a7e6266523e8f7e1150/
Traceback (most recent call last):
  File "/home/krishna/Desktop/ProjectTemplates/djangoBootstrapAuthTemplate/env/lib/python3.6/site-packages/django/core/handlers/exception.py", line 47, in inner
    response = get_response(request)
  File "/home/krishna/Desktop/ProjectTemplates/djangoBootstrapAuthTemplate/env/lib/python3.6/site-packages/django/core/handlers/base.py", line 181, in _get_response
    response = wrapped_callback(request, *callback_args, **callback_kwargs)
  File "/home/krishna/Desktop/ProjectTemplates/djangoBootstrapAuthTemplate/src/account/views.py", line 122, in activate
    user = User.objects.get(pk=uid)
  File "/home/krishna/Desktop/ProjectTemplates/djangoBootstrapAuthTemplate/env/lib/python3.6/site-packages/django/db/models/manager.py", line 191, in __get__
    cls._meta.swapped,
AttributeError: Manager isn't available; 'auth.User' has been swapped for 'account.Account'
ERROR 2021-02-16 15:59:47,445 basehttp 31956 139680817501952 "GET /account/activate/OQ/ai6739-7701f30b58ca5a7e6266523e8f7e1150/ HTTP/1.1" 500 87714
ERROR 2021-02-16 15:59:47,445 basehttp 31956 139680817501952 "GET /account/activate/OQ/ai6739-7701f30b58ca5a7e6266523e8f7e1150/ HTTP/1.1" 500 87714
ERROR 2021-02-16 16:16:52,635 log 32282 140036884039424 Internal Server Error: /account/password_reset/
Traceback (most recent call last):
  File "/home/krishna/Desktop/ProjectTemplates/djangoBootstrapAuthTemplate/env/lib/python3.6/site-packages/django/core/handlers/exception.py", line 47, in inner
    response = get_response(request)
  File "/home/krishna/Desktop/ProjectTemplates/djangoBootstrapAuthTemplate/env/lib/python3.6/site-packages/django/core/handlers/base.py", line 181, in _get_response
    response = wrapped_callback(request, *callback_args, **callback_kwargs)
  File "/home/krishna/Desktop/ProjectTemplates/djangoBootstrapAuthTemplate/env/lib/python3.6/site-packages/django/views/generic/base.py", line 70, in view
    return self.dispatch(request, *args, **kwargs)
  File "/home/krishna/Desktop/ProjectTemplates/djangoBootstrapAuthTemplate/env/lib/python3.6/site-packages/django/utils/decorators.py", line 43, in _wrapper
    return bound_method(*args, **kwargs)
  File "/home/krishna/Desktop/ProjectTemplates/djangoBootstrapAuthTemplate/env/lib/python3.6/site-packages/django/utils/decorators.py", line 130, in _wrapped_view
    response = view_func(request, *args, **kwargs)
  File "/home/krishna/Desktop/ProjectTemplates/djangoBootstrapAuthTemplate/env/lib/python3.6/site-packages/django/contrib/auth/views.py", line 222, in dispatch
    return super().dispatch(*args, **kwargs)
  File "/home/krishna/Desktop/ProjectTemplates/djangoBootstrapAuthTemplate/env/lib/python3.6/site-packages/django/views/generic/base.py", line 98, in dispatch
    return handler(request, *args, **kwargs)
  File "/home/krishna/Desktop/ProjectTemplates/djangoBootstrapAuthTemplate/env/lib/python3.6/site-packages/django/views/generic/edit.py", line 142, in post
    return self.form_valid(form)
  File "/home/krishna/Desktop/ProjectTemplates/djangoBootstrapAuthTemplate/env/lib/python3.6/site-packages/django/contrib/auth/views.py", line 235, in form_valid
    form.save(**opts)
  File "/home/krishna/Desktop/ProjectTemplates/djangoBootstrapAuthTemplate/env/lib/python3.6/site-packages/django/contrib/auth/forms.py", line 325, in save
    user_email, html_email_template_name=html_email_template_name,
  File "/home/krishna/Desktop/ProjectTemplates/djangoBootstrapAuthTemplate/env/lib/python3.6/site-packages/django/contrib/auth/forms.py", line 273, in send_mail
    email_message.send()
  File "/home/krishna/Desktop/ProjectTemplates/djangoBootstrapAuthTemplate/env/lib/python3.6/site-packages/django/core/mail/message.py", line 284, in send
    return self.get_connection(fail_silently).send_messages([self])
  File "/home/krishna/Desktop/ProjectTemplates/djangoBootstrapAuthTemplate/env/lib/python3.6/site-packages/django/core/mail/backends/smtp.py", line 102, in send_messages
    new_conn_created = self.open()
  File "/home/krishna/Desktop/ProjectTemplates/djangoBootstrapAuthTemplate/env/lib/python3.6/site-packages/django/core/mail/backends/smtp.py", line 62, in open
    self.connection = self.connection_class(self.host, self.port, **connection_params)
  File "/usr/lib/python3.6/smtplib.py", line 251, in __init__
    (code, msg) = self.connect(host, port)
  File "/usr/lib/python3.6/smtplib.py", line 336, in connect
    self.sock = self._get_socket(host, port, self.timeout)
  File "/usr/lib/python3.6/smtplib.py", line 307, in _get_socket
    self.source_address)
  File "/usr/lib/python3.6/socket.py", line 704, in create_connection
    for res in getaddrinfo(host, port, 0, SOCK_STREAM):
  File "/usr/lib/python3.6/socket.py", line 745, in getaddrinfo
    for res in _socket.getaddrinfo(host, port, family, type, proto, flags):
socket.gaierror: [Errno -2] Name or service not known
ERROR 2021-02-16 16:16:52,635 log 32282 140036884039424 Internal Server Error: /account/password_reset/
Traceback (most recent call last):
  File "/home/krishna/Desktop/ProjectTemplates/djangoBootstrapAuthTemplate/env/lib/python3.6/site-packages/django/core/handlers/exception.py", line 47, in inner
    response = get_response(request)
  File "/home/krishna/Desktop/ProjectTemplates/djangoBootstrapAuthTemplate/env/lib/python3.6/site-packages/django/core/handlers/base.py", line 181, in _get_response
    response = wrapped_callback(request, *callback_args, **callback_kwargs)
  File "/home/krishna/Desktop/ProjectTemplates/djangoBootstrapAuthTemplate/env/lib/python3.6/site-packages/django/views/generic/base.py", line 70, in view
    return self.dispatch(request, *args, **kwargs)
  File "/home/krishna/Desktop/ProjectTemplates/djangoBootstrapAuthTemplate/env/lib/python3.6/site-packages/django/utils/decorators.py", line 43, in _wrapper
    return bound_method(*args, **kwargs)
  File "/home/krishna/Desktop/ProjectTemplates/djangoBootstrapAuthTemplate/env/lib/python3.6/site-packages/django/utils/decorators.py", line 130, in _wrapped_view
    response = view_func(request, *args, **kwargs)
  File "/home/krishna/Desktop/ProjectTemplates/djangoBootstrapAuthTemplate/env/lib/python3.6/site-packages/django/contrib/auth/views.py", line 222, in dispatch
    return super().dispatch(*args, **kwargs)
  File "/home/krishna/Desktop/ProjectTemplates/djangoBootstrapAuthTemplate/env/lib/python3.6/site-packages/django/views/generic/base.py", line 98, in dispatch
    return handler(request, *args, **kwargs)
  File "/home/krishna/Desktop/ProjectTemplates/djangoBootstrapAuthTemplate/env/lib/python3.6/site-packages/django/views/generic/edit.py", line 142, in post
    return self.form_valid(form)
  File "/home/krishna/Desktop/ProjectTemplates/djangoBootstrapAuthTemplate/env/lib/python3.6/site-packages/django/contrib/auth/views.py", line 235, in form_valid
    form.save(**opts)
  File "/home/krishna/Desktop/ProjectTemplates/djangoBootstrapAuthTemplate/env/lib/python3.6/site-packages/django/contrib/auth/forms.py", line 325, in save
    user_email, html_email_template_name=html_email_template_name,
  File "/home/krishna/Desktop/ProjectTemplates/djangoBootstrapAuthTemplate/env/lib/python3.6/site-packages/django/contrib/auth/forms.py", line 273, in send_mail
    email_message.send()
  File "/home/krishna/Desktop/ProjectTemplates/djangoBootstrapAuthTemplate/env/lib/python3.6/site-packages/django/core/mail/message.py", line 284, in send
    return self.get_connection(fail_silently).send_messages([self])
  File "/home/krishna/Desktop/ProjectTemplates/djangoBootstrapAuthTemplate/env/lib/python3.6/site-packages/django/core/mail/backends/smtp.py", line 102, in send_messages
    new_conn_created = self.open()
  File "/home/krishna/Desktop/ProjectTemplates/djangoBootstrapAuthTemplate/env/lib/python3.6/site-packages/django/core/mail/backends/smtp.py", line 62, in open
    self.connection = self.connection_class(self.host, self.port, **connection_params)
  File "/usr/lib/python3.6/smtplib.py", line 251, in __init__
    (code, msg) = self.connect(host, port)
  File "/usr/lib/python3.6/smtplib.py", line 336, in connect
    self.sock = self._get_socket(host, port, self.timeout)
  File "/usr/lib/python3.6/smtplib.py", line 307, in _get_socket
    self.source_address)
  File "/usr/lib/python3.6/socket.py", line 704, in create_connection
    for res in getaddrinfo(host, port, 0, SOCK_STREAM):
  File "/usr/lib/python3.6/socket.py", line 745, in getaddrinfo
    for res in _socket.getaddrinfo(host, port, family, type, proto, flags):
socket.gaierror: [Errno -2] Name or service not known
ERROR 2021-02-16 16:16:52,699 basehttp 32282 140036884039424 "POST /account/password_reset/ HTTP/1.1" 500 162577
ERROR 2021-02-16 16:16:52,699 basehttp 32282 140036884039424 "POST /account/password_reset/ HTTP/1.1" 500 162577
ERROR 2021-02-16 16:27:40,606 log 1838 140066110764800 Internal Server Error: /account/password_reset/
Traceback (most recent call last):
  File "/home/krishna/Desktop/ProjectTemplates/djangoBootstrapAuthTemplate/env/lib/python3.6/site-packages/django/core/handlers/exception.py", line 47, in inner
    response = get_response(request)
  File "/home/krishna/Desktop/ProjectTemplates/djangoBootstrapAuthTemplate/env/lib/python3.6/site-packages/django/core/handlers/base.py", line 181, in _get_response
    response = wrapped_callback(request, *callback_args, **callback_kwargs)
  File "/home/krishna/Desktop/ProjectTemplates/djangoBootstrapAuthTemplate/env/lib/python3.6/site-packages/django/views/generic/base.py", line 70, in view
    return self.dispatch(request, *args, **kwargs)
  File "/home/krishna/Desktop/ProjectTemplates/djangoBootstrapAuthTemplate/env/lib/python3.6/site-packages/django/utils/decorators.py", line 43, in _wrapper
    return bound_method(*args, **kwargs)
  File "/home/krishna/Desktop/ProjectTemplates/djangoBootstrapAuthTemplate/env/lib/python3.6/site-packages/django/utils/decorators.py", line 130, in _wrapped_view
    response = view_func(request, *args, **kwargs)
  File "/home/krishna/Desktop/ProjectTemplates/djangoBootstrapAuthTemplate/env/lib/python3.6/site-packages/django/contrib/auth/views.py", line 222, in dispatch
    return super().dispatch(*args, **kwargs)
  File "/home/krishna/Desktop/ProjectTemplates/djangoBootstrapAuthTemplate/env/lib/python3.6/site-packages/django/views/generic/base.py", line 98, in dispatch
    return handler(request, *args, **kwargs)
  File "/home/krishna/Desktop/ProjectTemplates/djangoBootstrapAuthTemplate/env/lib/python3.6/site-packages/django/views/generic/edit.py", line 142, in post
    return self.form_valid(form)
  File "/home/krishna/Desktop/ProjectTemplates/djangoBootstrapAuthTemplate/env/lib/python3.6/site-packages/django/contrib/auth/views.py", line 235, in form_valid
    form.save(**opts)
  File "/home/krishna/Desktop/ProjectTemplates/djangoBootstrapAuthTemplate/env/lib/python3.6/site-packages/django/contrib/auth/forms.py", line 325, in save
    user_email, html_email_template_name=html_email_template_name,
  File "/home/krishna/Desktop/ProjectTemplates/djangoBootstrapAuthTemplate/env/lib/python3.6/site-packages/django/contrib/auth/forms.py", line 273, in send_mail
    email_message.send()
  File "/home/krishna/Desktop/ProjectTemplates/djangoBootstrapAuthTemplate/env/lib/python3.6/site-packages/django/core/mail/message.py", line 284, in send
    return self.get_connection(fail_silently).send_messages([self])
  File "/home/krishna/Desktop/ProjectTemplates/djangoBootstrapAuthTemplate/env/lib/python3.6/site-packages/django/core/mail/backends/smtp.py", line 102, in send_messages
    new_conn_created = self.open()
  File "/home/krishna/Desktop/ProjectTemplates/djangoBootstrapAuthTemplate/env/lib/python3.6/site-packages/django/core/mail/backends/smtp.py", line 62, in open
    self.connection = self.connection_class(self.host, self.port, **connection_params)
  File "/usr/lib/python3.6/smtplib.py", line 251, in __init__
    (code, msg) = self.connect(host, port)
  File "/usr/lib/python3.6/smtplib.py", line 336, in connect
    self.sock = self._get_socket(host, port, self.timeout)
  File "/usr/lib/python3.6/smtplib.py", line 307, in _get_socket
    self.source_address)
  File "/usr/lib/python3.6/socket.py", line 704, in create_connection
    for res in getaddrinfo(host, port, 0, SOCK_STREAM):
  File "/usr/lib/python3.6/socket.py", line 745, in getaddrinfo
    for res in _socket.getaddrinfo(host, port, family, type, proto, flags):
socket.gaierror: [Errno -2] Name or service not known
ERROR 2021-02-16 16:27:40,606 log 1838 140066110764800 Internal Server Error: /account/password_reset/
Traceback (most recent call last):
  File "/home/krishna/Desktop/ProjectTemplates/djangoBootstrapAuthTemplate/env/lib/python3.6/site-packages/django/core/handlers/exception.py", line 47, in inner
    response = get_response(request)
  File "/home/krishna/Desktop/ProjectTemplates/djangoBootstrapAuthTemplate/env/lib/python3.6/site-packages/django/core/handlers/base.py", line 181, in _get_response
    response = wrapped_callback(request, *callback_args, **callback_kwargs)
  File "/home/krishna/Desktop/ProjectTemplates/djangoBootstrapAuthTemplate/env/lib/python3.6/site-packages/django/views/generic/base.py", line 70, in view
    return self.dispatch(request, *args, **kwargs)
  File "/home/krishna/Desktop/ProjectTemplates/djangoBootstrapAuthTemplate/env/lib/python3.6/site-packages/django/utils/decorators.py", line 43, in _wrapper
    return bound_method(*args, **kwargs)
  File "/home/krishna/Desktop/ProjectTemplates/djangoBootstrapAuthTemplate/env/lib/python3.6/site-packages/django/utils/decorators.py", line 130, in _wrapped_view
    response = view_func(request, *args, **kwargs)
  File "/home/krishna/Desktop/ProjectTemplates/djangoBootstrapAuthTemplate/env/lib/python3.6/site-packages/django/contrib/auth/views.py", line 222, in dispatch
    return super().dispatch(*args, **kwargs)
  File "/home/krishna/Desktop/ProjectTemplates/djangoBootstrapAuthTemplate/env/lib/python3.6/site-packages/django/views/generic/base.py", line 98, in dispatch
    return handler(request, *args, **kwargs)
  File "/home/krishna/Desktop/ProjectTemplates/djangoBootstrapAuthTemplate/env/lib/python3.6/site-packages/django/views/generic/edit.py", line 142, in post
    return self.form_valid(form)
  File "/home/krishna/Desktop/ProjectTemplates/djangoBootstrapAuthTemplate/env/lib/python3.6/site-packages/django/contrib/auth/views.py", line 235, in form_valid
    form.save(**opts)
  File "/home/krishna/Desktop/ProjectTemplates/djangoBootstrapAuthTemplate/env/lib/python3.6/site-packages/django/contrib/auth/forms.py", line 325, in save
    user_email, html_email_template_name=html_email_template_name,
  File "/home/krishna/Desktop/ProjectTemplates/djangoBootstrapAuthTemplate/env/lib/python3.6/site-packages/django/contrib/auth/forms.py", line 273, in send_mail
    email_message.send()
  File "/home/krishna/Desktop/ProjectTemplates/djangoBootstrapAuthTemplate/env/lib/python3.6/site-packages/django/core/mail/message.py", line 284, in send
    return self.get_connection(fail_silently).send_messages([self])
  File "/home/krishna/Desktop/ProjectTemplates/djangoBootstrapAuthTemplate/env/lib/python3.6/site-packages/django/core/mail/backends/smtp.py", line 102, in send_messages
    new_conn_created = self.open()
  File "/home/krishna/Desktop/ProjectTemplates/djangoBootstrapAuthTemplate/env/lib/python3.6/site-packages/django/core/mail/backends/smtp.py", line 62, in open
    self.connection = self.connection_class(self.host, self.port, **connection_params)
  File "/usr/lib/python3.6/smtplib.py", line 251, in __init__
    (code, msg) = self.connect(host, port)
  File "/usr/lib/python3.6/smtplib.py", line 336, in connect
    self.sock = self._get_socket(host, port, self.timeout)
  File "/usr/lib/python3.6/smtplib.py", line 307, in _get_socket
    self.source_address)
  File "/usr/lib/python3.6/socket.py", line 704, in create_connection
    for res in getaddrinfo(host, port, 0, SOCK_STREAM):
  File "/usr/lib/python3.6/socket.py", line 745, in getaddrinfo
    for res in _socket.getaddrinfo(host, port, family, type, proto, flags):
socket.gaierror: [Errno -2] Name or service not known
ERROR 2021-02-16 16:27:40,645 basehttp 1838 140066110764800 "POST /account/password_reset/ HTTP/1.1" 500 162577
ERROR 2021-02-16 16:27:40,645 basehttp 1838 140066110764800 "POST /account/password_reset/ HTTP/1.1" 500 162577
