WARNING 2021-02-13 11:07:36,812 log 16979 139748364945152 Not Found: /favicon.ico
WARNING 2021-02-13 11:07:36,812 log 16979 139748364945152 Not Found: /favicon.ico
WARNING 2021-02-13 11:07:36,813 basehttp 16979 139748364945152 "GET /favicon.ico HTTP/1.1" 404 12525
WARNING 2021-02-13 11:07:36,813 basehttp 16979 139748364945152 "GET /favicon.ico HTTP/1.1" 404 12525
ERROR 2021-02-13 11:07:46,142 log 16979 139748364945152 Internal Server Error: /admin/
Traceback (most recent call last):
  File "/home/krishna/Desktop/ProjectTemplates/djangoBootstrapAuthTemplate/env/lib/python3.6/site-packages/django/core/handlers/exception.py", line 47, in inner
    response = get_response(request)
  File "/home/krishna/Desktop/ProjectTemplates/djangoBootstrapAuthTemplate/env/lib/python3.6/site-packages/django/core/handlers/base.py", line 181, in _get_response
    response = wrapped_callback(request, *callback_args, **callback_kwargs)
  File "/home/krishna/Desktop/ProjectTemplates/djangoBootstrapAuthTemplate/env/lib/python3.6/site-packages/django/contrib/admin/sites.py", line 251, in wrapper
    return self.admin_view(view, cacheable)(*args, **kwargs)
  File "/home/krishna/Desktop/ProjectTemplates/djangoBootstrapAuthTemplate/env/lib/python3.6/site-packages/django/utils/decorators.py", line 130, in _wrapped_view
    response = view_func(request, *args, **kwargs)
  File "/home/krishna/Desktop/ProjectTemplates/djangoBootstrapAuthTemplate/env/lib/python3.6/site-packages/django/views/decorators/cache.py", line 44, in _wrapped_view_func
    response = view_func(request, *args, **kwargs)
  File "/home/krishna/Desktop/ProjectTemplates/djangoBootstrapAuthTemplate/env/lib/python3.6/site-packages/django/contrib/admin/sites.py", line 233, in inner
    return view(request, *args, **kwargs)
  File "/home/krishna/Desktop/ProjectTemplates/djangoBootstrapAuthTemplate/env/lib/python3.6/site-packages/django/views/decorators/cache.py", line 44, in _wrapped_view_func
    response = view_func(request, *args, **kwargs)
  File "/home/krishna/Desktop/ProjectTemplates/djangoBootstrapAuthTemplate/env/lib/python3.6/site-packages/django/contrib/admin/sites.py", line 502, in index
    app_list = self.get_app_list(request)
  File "/home/krishna/Desktop/ProjectTemplates/djangoBootstrapAuthTemplate/env/lib/python3.6/site-packages/django/contrib/admin/sites.py", line 485, in get_app_list
    app_dict = self._build_app_dict(request)
  File "/home/krishna/Desktop/ProjectTemplates/djangoBootstrapAuthTemplate/env/lib/python3.6/site-packages/django/contrib/admin/sites.py", line 434, in _build_app_dict
    perms = model_admin.get_model_perms(request)
  File "/home/krishna/Desktop/ProjectTemplates/djangoBootstrapAuthTemplate/env/lib/python3.6/site-packages/django/contrib/admin/options.py", line 659, in get_model_perms
    'add': self.has_add_permission(request),
  File "/home/krishna/Desktop/ProjectTemplates/djangoBootstrapAuthTemplate/env/lib/python3.6/site-packages/django/contrib/admin/options.py", line 481, in has_add_permission
    return request.user.has_perm("%s.%s" % (opts.app_label, codename))
TypeError: has_perm() takes 1 positional argument but 2 were given
ERROR 2021-02-13 11:07:46,142 log 16979 139748364945152 Internal Server Error: /admin/
Traceback (most recent call last):
  File "/home/krishna/Desktop/ProjectTemplates/djangoBootstrapAuthTemplate/env/lib/python3.6/site-packages/django/core/handlers/exception.py", line 47, in inner
    response = get_response(request)
  File "/home/krishna/Desktop/ProjectTemplates/djangoBootstrapAuthTemplate/env/lib/python3.6/site-packages/django/core/handlers/base.py", line 181, in _get_response
    response = wrapped_callback(request, *callback_args, **callback_kwargs)
  File "/home/krishna/Desktop/ProjectTemplates/djangoBootstrapAuthTemplate/env/lib/python3.6/site-packages/django/contrib/admin/sites.py", line 251, in wrapper
    return self.admin_view(view, cacheable)(*args, **kwargs)
  File "/home/krishna/Desktop/ProjectTemplates/djangoBootstrapAuthTemplate/env/lib/python3.6/site-packages/django/utils/decorators.py", line 130, in _wrapped_view
    response = view_func(request, *args, **kwargs)
  File "/home/krishna/Desktop/ProjectTemplates/djangoBootstrapAuthTemplate/env/lib/python3.6/site-packages/django/views/decorators/cache.py", line 44, in _wrapped_view_func
    response = view_func(request, *args, **kwargs)
  File "/home/krishna/Desktop/ProjectTemplates/djangoBootstrapAuthTemplate/env/lib/python3.6/site-packages/django/contrib/admin/sites.py", line 233, in inner
    return view(request, *args, **kwargs)
  File "/home/krishna/Desktop/ProjectTemplates/djangoBootstrapAuthTemplate/env/lib/python3.6/site-packages/django/views/decorators/cache.py", line 44, in _wrapped_view_func
    response = view_func(request, *args, **kwargs)
  File "/home/krishna/Desktop/ProjectTemplates/djangoBootstrapAuthTemplate/env/lib/python3.6/site-packages/django/contrib/admin/sites.py", line 502, in index
    app_list = self.get_app_list(request)
  File "/home/krishna/Desktop/ProjectTemplates/djangoBootstrapAuthTemplate/env/lib/python3.6/site-packages/django/contrib/admin/sites.py", line 485, in get_app_list
    app_dict = self._build_app_dict(request)
  File "/home/krishna/Desktop/ProjectTemplates/djangoBootstrapAuthTemplate/env/lib/python3.6/site-packages/django/contrib/admin/sites.py", line 434, in _build_app_dict
    perms = model_admin.get_model_perms(request)
  File "/home/krishna/Desktop/ProjectTemplates/djangoBootstrapAuthTemplate/env/lib/python3.6/site-packages/django/contrib/admin/options.py", line 659, in get_model_perms
    'add': self.has_add_permission(request),
  File "/home/krishna/Desktop/ProjectTemplates/djangoBootstrapAuthTemplate/env/lib/python3.6/site-packages/django/contrib/admin/options.py", line 481, in has_add_permission
    return request.user.has_perm("%s.%s" % (opts.app_label, codename))
TypeError: has_perm() takes 1 positional argument but 2 were given
ERROR 2021-02-13 11:07:46,206 basehttp 16979 139748364945152 "GET /admin/ HTTP/1.1" 500 123462
ERROR 2021-02-13 11:07:46,206 basehttp 16979 139748364945152 "GET /admin/ HTTP/1.1" 500 123462
ERROR 2021-02-13 13:10:31,464 log 23415 139811503904512 Internal Server Error: /account/register/
Traceback (most recent call last):
  File "/home/krishna/Desktop/ProjectTemplates/djangoBootstrapAuthTemplate/env/lib/python3.6/site-packages/django/core/handlers/exception.py", line 47, in inner
    response = get_response(request)
  File "/home/krishna/Desktop/ProjectTemplates/djangoBootstrapAuthTemplate/env/lib/python3.6/site-packages/django/core/handlers/base.py", line 181, in _get_response
    response = wrapped_callback(request, *callback_args, **callback_kwargs)
  File "/home/krishna/Desktop/ProjectTemplates/djangoBootstrapAuthTemplate/src/account/views.py", line 16, in registration_view
    account = authenticate(email, raw_password)
TypeError: authenticate() takes from 0 to 1 positional arguments but 2 were given
ERROR 2021-02-13 13:10:31,464 log 23415 139811503904512 Internal Server Error: /account/register/
Traceback (most recent call last):
  File "/home/krishna/Desktop/ProjectTemplates/djangoBootstrapAuthTemplate/env/lib/python3.6/site-packages/django/core/handlers/exception.py", line 47, in inner
    response = get_response(request)
  File "/home/krishna/Desktop/ProjectTemplates/djangoBootstrapAuthTemplate/env/lib/python3.6/site-packages/django/core/handlers/base.py", line 181, in _get_response
    response = wrapped_callback(request, *callback_args, **callback_kwargs)
  File "/home/krishna/Desktop/ProjectTemplates/djangoBootstrapAuthTemplate/src/account/views.py", line 16, in registration_view
    account = authenticate(email, raw_password)
TypeError: authenticate() takes from 0 to 1 positional arguments but 2 were given
ERROR 2021-02-13 13:10:31,530 basehttp 23415 139811503904512 "POST /account/register/ HTTP/1.1" 500 84785
ERROR 2021-02-13 13:10:31,530 basehttp 23415 139811503904512 "POST /account/register/ HTTP/1.1" 500 84785
WARNING 2021-02-13 13:11:52,920 views 23575 140126751426304 request is processing
WARNING 2021-02-13 13:44:01,354 views 25240 140277364905728 request is processing
WARNING 2021-02-13 14:41:44,007 views 25240 140277364905728 request is processing
WARNING 2021-02-13 14:41:58,611 views 25240 140277364905728 request is processing
WARNING 2021-02-13 14:42:00,917 views 25240 140277364905728 request is processing
WARNING 2021-02-13 14:42:03,036 views 25240 140277364905728 request is processing
WARNING 2021-02-13 14:42:06,994 views 25240 140277364905728 request is processing
WARNING 2021-02-13 14:42:48,951 views 25240 140277364905728 request is processing
WARNING 2021-02-13 15:15:25,761 views 29311 140028259104512 request is processing
WARNING 2021-02-13 15:15:29,178 views 29311 140028259104512 request is processing
WARNING 2021-02-13 15:15:35,382 views 29311 140028259104512 request is processing
WARNING 2021-02-13 15:18:49,707 views 30077 140535373321984 request is processing
WARNING 2021-02-13 15:19:08,235 views 30077 140535373321984 request is processing
WARNING 2021-02-13 15:19:51,091 views 30077 140535373321984 request is processing
WARNING 2021-02-13 15:20:10,477 views 30077 140535373321984 request is processing
WARNING 2021-02-13 15:20:47,363 views 30077 140535373321984 request is processing
ERROR 2021-02-13 15:21:02,371 log 30077 140535373321984 Internal Server Error: /account/login/
Traceback (most recent call last):
  File "/home/krishna/Desktop/ProjectTemplates/djangoBootstrapAuthTemplate/env/lib/python3.6/site-packages/django/core/handlers/exception.py", line 47, in inner
    response = get_response(request)
  File "/home/krishna/Desktop/ProjectTemplates/djangoBootstrapAuthTemplate/env/lib/python3.6/site-packages/django/core/handlers/base.py", line 181, in _get_response
    response = wrapped_callback(request, *callback_args, **callback_kwargs)
  File "/home/krishna/Desktop/ProjectTemplates/djangoBootstrapAuthTemplate/src/account/views.py", line 39, in login_view
    if form.is_valid():
  File "/home/krishna/Desktop/ProjectTemplates/djangoBootstrapAuthTemplate/env/lib/python3.6/site-packages/django/forms/forms.py", line 177, in is_valid
    return self.is_bound and not self.errors
  File "/home/krishna/Desktop/ProjectTemplates/djangoBootstrapAuthTemplate/env/lib/python3.6/site-packages/django/forms/forms.py", line 172, in errors
    self.full_clean()
  File "/home/krishna/Desktop/ProjectTemplates/djangoBootstrapAuthTemplate/env/lib/python3.6/site-packages/django/forms/forms.py", line 375, in full_clean
    self._clean_form()
  File "/home/krishna/Desktop/ProjectTemplates/djangoBootstrapAuthTemplate/env/lib/python3.6/site-packages/django/forms/forms.py", line 402, in _clean_form
    cleaned_data = self.clean()
  File "/home/krishna/Desktop/ProjectTemplates/djangoBootstrapAuthTemplate/src/account/forms.py", line 23, in clean
    email = self.cleaned_data['email']
KeyError: 'email'
ERROR 2021-02-13 15:21:02,371 log 30077 140535373321984 Internal Server Error: /account/login/
Traceback (most recent call last):
  File "/home/krishna/Desktop/ProjectTemplates/djangoBootstrapAuthTemplate/env/lib/python3.6/site-packages/django/core/handlers/exception.py", line 47, in inner
    response = get_response(request)
  File "/home/krishna/Desktop/ProjectTemplates/djangoBootstrapAuthTemplate/env/lib/python3.6/site-packages/django/core/handlers/base.py", line 181, in _get_response
    response = wrapped_callback(request, *callback_args, **callback_kwargs)
  File "/home/krishna/Desktop/ProjectTemplates/djangoBootstrapAuthTemplate/src/account/views.py", line 39, in login_view
    if form.is_valid():
  File "/home/krishna/Desktop/ProjectTemplates/djangoBootstrapAuthTemplate/env/lib/python3.6/site-packages/django/forms/forms.py", line 177, in is_valid
    return self.is_bound and not self.errors
  File "/home/krishna/Desktop/ProjectTemplates/djangoBootstrapAuthTemplate/env/lib/python3.6/site-packages/django/forms/forms.py", line 172, in errors
    self.full_clean()
  File "/home/krishna/Desktop/ProjectTemplates/djangoBootstrapAuthTemplate/env/lib/python3.6/site-packages/django/forms/forms.py", line 375, in full_clean
    self._clean_form()
  File "/home/krishna/Desktop/ProjectTemplates/djangoBootstrapAuthTemplate/env/lib/python3.6/site-packages/django/forms/forms.py", line 402, in _clean_form
    cleaned_data = self.clean()
  File "/home/krishna/Desktop/ProjectTemplates/djangoBootstrapAuthTemplate/src/account/forms.py", line 23, in clean
    email = self.cleaned_data['email']
KeyError: 'email'
ERROR 2021-02-13 15:21:02,416 basehttp 30077 140535373321984 "POST /account/login/ HTTP/1.1" 500 101916
ERROR 2021-02-13 15:21:02,416 basehttp 30077 140535373321984 "POST /account/login/ HTTP/1.1" 500 101916
WARNING 2021-02-13 15:35:55,360 views 30682 139872351950592 request is processing
WARNING 2021-02-13 16:18:11,792 views 32524 140380503725824 request is processing
WARNING 2021-02-13 16:25:49,140 views 1504 140555489113856 request is processing
WARNING 2021-02-13 16:27:28,930 views 1755 140078912014080 request is processing
WARNING 2021-02-13 16:27:35,770 views 1755 140078912014080 request is processing
WARNING 2021-02-13 16:27:52,089 views 1755 140078912014080 request is processing
WARNING 2021-02-13 16:28:43,700 views 1878 140714939774720 request is processing
WARNING 2021-02-13 16:30:06,499 views 1878 140714939774720 request is processing
WARNING 2021-02-13 16:31:02,782 views 1878 140714939774720 request is processing
ERROR 2021-02-13 16:32:59,152 log 1878 140714939774720 Internal Server Error: /account/login/
Traceback (most recent call last):
  File "/home/krishna/Desktop/ProjectTemplates/djangoBootstrapAuthTemplate/env/lib/python3.6/site-packages/django/template/backends/django.py", line 61, in render
    return self.template.render(context)
  File "/home/krishna/Desktop/ProjectTemplates/djangoBootstrapAuthTemplate/env/lib/python3.6/site-packages/django/template/base.py", line 170, in render
    return self._render(context)
  File "/home/krishna/Desktop/ProjectTemplates/djangoBootstrapAuthTemplate/env/lib/python3.6/site-packages/django/test/utils.py", line 96, in instrumented_test_render
    return self.nodelist.render(context)
  File "/home/krishna/Desktop/ProjectTemplates/djangoBootstrapAuthTemplate/env/lib/python3.6/site-packages/django/template/base.py", line 938, in render
    bit = node.render_annotated(context)
  File "/home/krishna/Desktop/ProjectTemplates/djangoBootstrapAuthTemplate/env/lib/python3.6/site-packages/django/template/base.py", line 905, in render_annotated
    return self.render(context)
  File "/home/krishna/Desktop/ProjectTemplates/djangoBootstrapAuthTemplate/env/lib/python3.6/site-packages/django/template/loader_tags.py", line 127, in render
    compiled_parent = self.get_parent(context)
  File "/home/krishna/Desktop/ProjectTemplates/djangoBootstrapAuthTemplate/env/lib/python3.6/site-packages/django/template/loader_tags.py", line 124, in get_parent
    return self.find_template(parent, context)
  File "/home/krishna/Desktop/ProjectTemplates/djangoBootstrapAuthTemplate/env/lib/python3.6/site-packages/django/template/loader_tags.py", line 104, in find_template
    template_name, skip=history,
  File "/home/krishna/Desktop/ProjectTemplates/djangoBootstrapAuthTemplate/env/lib/python3.6/site-packages/django/template/engine.py", line 129, in find_template
    raise TemplateDoesNotExist(name, tried=tried)
django.template.exceptions.TemplateDoesNotExist: base.html

The above exception was the direct cause of the following exception:

Traceback (most recent call last):
  File "/home/krishna/Desktop/ProjectTemplates/djangoBootstrapAuthTemplate/env/lib/python3.6/site-packages/django/core/handlers/exception.py", line 47, in inner
    response = get_response(request)
  File "/home/krishna/Desktop/ProjectTemplates/djangoBootstrapAuthTemplate/env/lib/python3.6/site-packages/django/core/handlers/base.py", line 181, in _get_response
    response = wrapped_callback(request, *callback_args, **callback_kwargs)
  File "/home/krishna/Desktop/ProjectTemplates/djangoBootstrapAuthTemplate/src/account/views.py", line 55, in login_view
    return render(request, 'account/login.html', context)
  File "/home/krishna/Desktop/ProjectTemplates/djangoBootstrapAuthTemplate/env/lib/python3.6/site-packages/django/shortcuts.py", line 19, in render
    content = loader.render_to_string(template_name, context, request, using=using)
  File "/home/krishna/Desktop/ProjectTemplates/djangoBootstrapAuthTemplate/env/lib/python3.6/site-packages/django/template/loader.py", line 62, in render_to_string
    return template.render(context, request)
  File "/home/krishna/Desktop/ProjectTemplates/djangoBootstrapAuthTemplate/env/lib/python3.6/site-packages/django/template/backends/django.py", line 63, in render
    reraise(exc, self.backend)
  File "/home/krishna/Desktop/ProjectTemplates/djangoBootstrapAuthTemplate/env/lib/python3.6/site-packages/django/template/backends/django.py", line 84, in reraise
    raise new from exc
django.template.exceptions.TemplateDoesNotExist: base.html
ERROR 2021-02-13 16:32:59,152 log 1878 140714939774720 Internal Server Error: /account/login/
Traceback (most recent call last):
  File "/home/krishna/Desktop/ProjectTemplates/djangoBootstrapAuthTemplate/env/lib/python3.6/site-packages/django/template/backends/django.py", line 61, in render
    return self.template.render(context)
  File "/home/krishna/Desktop/ProjectTemplates/djangoBootstrapAuthTemplate/env/lib/python3.6/site-packages/django/template/base.py", line 170, in render
    return self._render(context)
  File "/home/krishna/Desktop/ProjectTemplates/djangoBootstrapAuthTemplate/env/lib/python3.6/site-packages/django/test/utils.py", line 96, in instrumented_test_render
    return self.nodelist.render(context)
  File "/home/krishna/Desktop/ProjectTemplates/djangoBootstrapAuthTemplate/env/lib/python3.6/site-packages/django/template/base.py", line 938, in render
    bit = node.render_annotated(context)
  File "/home/krishna/Desktop/ProjectTemplates/djangoBootstrapAuthTemplate/env/lib/python3.6/site-packages/django/template/base.py", line 905, in render_annotated
    return self.render(context)
  File "/home/krishna/Desktop/ProjectTemplates/djangoBootstrapAuthTemplate/env/lib/python3.6/site-packages/django/template/loader_tags.py", line 127, in render
    compiled_parent = self.get_parent(context)
  File "/home/krishna/Desktop/ProjectTemplates/djangoBootstrapAuthTemplate/env/lib/python3.6/site-packages/django/template/loader_tags.py", line 124, in get_parent
    return self.find_template(parent, context)
  File "/home/krishna/Desktop/ProjectTemplates/djangoBootstrapAuthTemplate/env/lib/python3.6/site-packages/django/template/loader_tags.py", line 104, in find_template
    template_name, skip=history,
  File "/home/krishna/Desktop/ProjectTemplates/djangoBootstrapAuthTemplate/env/lib/python3.6/site-packages/django/template/engine.py", line 129, in find_template
    raise TemplateDoesNotExist(name, tried=tried)
django.template.exceptions.TemplateDoesNotExist: base.html

The above exception was the direct cause of the following exception:

Traceback (most recent call last):
  File "/home/krishna/Desktop/ProjectTemplates/djangoBootstrapAuthTemplate/env/lib/python3.6/site-packages/django/core/handlers/exception.py", line 47, in inner
    response = get_response(request)
  File "/home/krishna/Desktop/ProjectTemplates/djangoBootstrapAuthTemplate/env/lib/python3.6/site-packages/django/core/handlers/base.py", line 181, in _get_response
    response = wrapped_callback(request, *callback_args, **callback_kwargs)
  File "/home/krishna/Desktop/ProjectTemplates/djangoBootstrapAuthTemplate/src/account/views.py", line 55, in login_view
    return render(request, 'account/login.html', context)
  File "/home/krishna/Desktop/ProjectTemplates/djangoBootstrapAuthTemplate/env/lib/python3.6/site-packages/django/shortcuts.py", line 19, in render
    content = loader.render_to_string(template_name, context, request, using=using)
  File "/home/krishna/Desktop/ProjectTemplates/djangoBootstrapAuthTemplate/env/lib/python3.6/site-packages/django/template/loader.py", line 62, in render_to_string
    return template.render(context, request)
  File "/home/krishna/Desktop/ProjectTemplates/djangoBootstrapAuthTemplate/env/lib/python3.6/site-packages/django/template/backends/django.py", line 63, in render
    reraise(exc, self.backend)
  File "/home/krishna/Desktop/ProjectTemplates/djangoBootstrapAuthTemplate/env/lib/python3.6/site-packages/django/template/backends/django.py", line 84, in reraise
    raise new from exc
django.template.exceptions.TemplateDoesNotExist: base.html
ERROR 2021-02-13 16:32:59,179 basehttp 1878 140714939774720 "GET /account/login/ HTTP/1.1" 500 144983
ERROR 2021-02-13 16:32:59,179 basehttp 1878 140714939774720 "GET /account/login/ HTTP/1.1" 500 144983
WARNING 2021-02-13 16:42:10,141 views 1878 140714939774720 request is processing
ERROR 2021-02-13 16:42:17,564 log 1878 140714939774720 Internal Server Error: /account/account/
Traceback (most recent call last):
  File "/home/krishna/Desktop/ProjectTemplates/djangoBootstrapAuthTemplate/env/lib/python3.6/site-packages/django/template/backends/django.py", line 61, in render
    return self.template.render(context)
  File "/home/krishna/Desktop/ProjectTemplates/djangoBootstrapAuthTemplate/env/lib/python3.6/site-packages/django/template/base.py", line 170, in render
    return self._render(context)
  File "/home/krishna/Desktop/ProjectTemplates/djangoBootstrapAuthTemplate/env/lib/python3.6/site-packages/django/test/utils.py", line 96, in instrumented_test_render
    return self.nodelist.render(context)
  File "/home/krishna/Desktop/ProjectTemplates/djangoBootstrapAuthTemplate/env/lib/python3.6/site-packages/django/template/base.py", line 938, in render
    bit = node.render_annotated(context)
  File "/home/krishna/Desktop/ProjectTemplates/djangoBootstrapAuthTemplate/env/lib/python3.6/site-packages/django/template/base.py", line 905, in render_annotated
    return self.render(context)
  File "/home/krishna/Desktop/ProjectTemplates/djangoBootstrapAuthTemplate/env/lib/python3.6/site-packages/django/template/loader_tags.py", line 127, in render
    compiled_parent = self.get_parent(context)
  File "/home/krishna/Desktop/ProjectTemplates/djangoBootstrapAuthTemplate/env/lib/python3.6/site-packages/django/template/loader_tags.py", line 124, in get_parent
    return self.find_template(parent, context)
  File "/home/krishna/Desktop/ProjectTemplates/djangoBootstrapAuthTemplate/env/lib/python3.6/site-packages/django/template/loader_tags.py", line 104, in find_template
    template_name, skip=history,
  File "/home/krishna/Desktop/ProjectTemplates/djangoBootstrapAuthTemplate/env/lib/python3.6/site-packages/django/template/engine.py", line 129, in find_template
    raise TemplateDoesNotExist(name, tried=tried)
django.template.exceptions.TemplateDoesNotExist: base.html

The above exception was the direct cause of the following exception:

Traceback (most recent call last):
  File "/home/krishna/Desktop/ProjectTemplates/djangoBootstrapAuthTemplate/env/lib/python3.6/site-packages/django/core/handlers/exception.py", line 47, in inner
    response = get_response(request)
  File "/home/krishna/Desktop/ProjectTemplates/djangoBootstrapAuthTemplate/env/lib/python3.6/site-packages/django/core/handlers/base.py", line 181, in _get_response
    response = wrapped_callback(request, *callback_args, **callback_kwargs)
  File "/home/krishna/Desktop/ProjectTemplates/djangoBootstrapAuthTemplate/src/account/views.py", line 77, in account_view
    return render(request, 'account/account.html', context)
  File "/home/krishna/Desktop/ProjectTemplates/djangoBootstrapAuthTemplate/env/lib/python3.6/site-packages/django/shortcuts.py", line 19, in render
    content = loader.render_to_string(template_name, context, request, using=using)
  File "/home/krishna/Desktop/ProjectTemplates/djangoBootstrapAuthTemplate/env/lib/python3.6/site-packages/django/template/loader.py", line 62, in render_to_string
    return template.render(context, request)
  File "/home/krishna/Desktop/ProjectTemplates/djangoBootstrapAuthTemplate/env/lib/python3.6/site-packages/django/template/backends/django.py", line 63, in render
    reraise(exc, self.backend)
  File "/home/krishna/Desktop/ProjectTemplates/djangoBootstrapAuthTemplate/env/lib/python3.6/site-packages/django/template/backends/django.py", line 84, in reraise
    raise new from exc
django.template.exceptions.TemplateDoesNotExist: base.html
ERROR 2021-02-13 16:42:17,564 log 1878 140714939774720 Internal Server Error: /account/account/
Traceback (most recent call last):
  File "/home/krishna/Desktop/ProjectTemplates/djangoBootstrapAuthTemplate/env/lib/python3.6/site-packages/django/template/backends/django.py", line 61, in render
    return self.template.render(context)
  File "/home/krishna/Desktop/ProjectTemplates/djangoBootstrapAuthTemplate/env/lib/python3.6/site-packages/django/template/base.py", line 170, in render
    return self._render(context)
  File "/home/krishna/Desktop/ProjectTemplates/djangoBootstrapAuthTemplate/env/lib/python3.6/site-packages/django/test/utils.py", line 96, in instrumented_test_render
    return self.nodelist.render(context)
  File "/home/krishna/Desktop/ProjectTemplates/djangoBootstrapAuthTemplate/env/lib/python3.6/site-packages/django/template/base.py", line 938, in render
    bit = node.render_annotated(context)
  File "/home/krishna/Desktop/ProjectTemplates/djangoBootstrapAuthTemplate/env/lib/python3.6/site-packages/django/template/base.py", line 905, in render_annotated
    return self.render(context)
  File "/home/krishna/Desktop/ProjectTemplates/djangoBootstrapAuthTemplate/env/lib/python3.6/site-packages/django/template/loader_tags.py", line 127, in render
    compiled_parent = self.get_parent(context)
  File "/home/krishna/Desktop/ProjectTemplates/djangoBootstrapAuthTemplate/env/lib/python3.6/site-packages/django/template/loader_tags.py", line 124, in get_parent
    return self.find_template(parent, context)
  File "/home/krishna/Desktop/ProjectTemplates/djangoBootstrapAuthTemplate/env/lib/python3.6/site-packages/django/template/loader_tags.py", line 104, in find_template
    template_name, skip=history,
  File "/home/krishna/Desktop/ProjectTemplates/djangoBootstrapAuthTemplate/env/lib/python3.6/site-packages/django/template/engine.py", line 129, in find_template
    raise TemplateDoesNotExist(name, tried=tried)
django.template.exceptions.TemplateDoesNotExist: base.html

The above exception was the direct cause of the following exception:

Traceback (most recent call last):
  File "/home/krishna/Desktop/ProjectTemplates/djangoBootstrapAuthTemplate/env/lib/python3.6/site-packages/django/core/handlers/exception.py", line 47, in inner
    response = get_response(request)
  File "/home/krishna/Desktop/ProjectTemplates/djangoBootstrapAuthTemplate/env/lib/python3.6/site-packages/django/core/handlers/base.py", line 181, in _get_response
    response = wrapped_callback(request, *callback_args, **callback_kwargs)
  File "/home/krishna/Desktop/ProjectTemplates/djangoBootstrapAuthTemplate/src/account/views.py", line 77, in account_view
    return render(request, 'account/account.html', context)
  File "/home/krishna/Desktop/ProjectTemplates/djangoBootstrapAuthTemplate/env/lib/python3.6/site-packages/django/shortcuts.py", line 19, in render
    content = loader.render_to_string(template_name, context, request, using=using)
  File "/home/krishna/Desktop/ProjectTemplates/djangoBootstrapAuthTemplate/env/lib/python3.6/site-packages/django/template/loader.py", line 62, in render_to_string
    return template.render(context, request)
  File "/home/krishna/Desktop/ProjectTemplates/djangoBootstrapAuthTemplate/env/lib/python3.6/site-packages/django/template/backends/django.py", line 63, in render
    reraise(exc, self.backend)
  File "/home/krishna/Desktop/ProjectTemplates/djangoBootstrapAuthTemplate/env/lib/python3.6/site-packages/django/template/backends/django.py", line 84, in reraise
    raise new from exc
django.template.exceptions.TemplateDoesNotExist: base.html
ERROR 2021-02-13 16:42:17,610 basehttp 1878 140714939774720 "GET /account/account/ HTTP/1.1" 500 144155
ERROR 2021-02-13 16:42:17,610 basehttp 1878 140714939774720 "GET /account/account/ HTTP/1.1" 500 144155
WARNING 2021-02-13 16:42:43,671 views 1878 140714939774720 request is processing
WARNING 2021-02-13 16:43:27,888 views 1878 140714939774720 request is processing
WARNING 2021-02-13 17:28:09,342 views 3606 140241553848064 request is processing
WARNING 2021-02-13 20:31:26,243 views 10819 140640061241088 request is processing
WARNING 2021-02-13 20:31:27,384 log 10819 140640061241088 Not Found: /favicon.ico
WARNING 2021-02-13 20:31:27,384 log 10819 140640061241088 Not Found: /favicon.ico
WARNING 2021-02-13 20:31:27,384 basehttp 10819 140640061241088 "GET /favicon.ico HTTP/1.1" 404 12538
WARNING 2021-02-13 20:31:27,384 basehttp 10819 140640061241088 "GET /favicon.ico HTTP/1.1" 404 12538
WARNING 2021-02-13 20:31:37,388 views 10819 140640061241088 request is processing
WARNING 2021-02-13 20:31:49,577 views 10819 140640061241088 request is processing
WARNING 2021-02-13 22:28:04,780 views 10819 140640061241088 request is processing
WARNING 2021-02-13 22:28:45,541 views 10819 140640061241088 request is processing
WARNING 2021-02-13 22:29:31,620 views 10819 140640061241088 request is processing
WARNING 2021-02-13 22:29:33,382 views 10819 140640061241088 request is processing
WARNING 2021-02-13 22:30:40,909 views 10819 140640061241088 request is processing
WARNING 2021-02-13 22:30:50,608 views 10819 140640061241088 request is processing
WARNING 2021-02-13 22:30:54,902 views 10819 140640061241088 request is processing
WARNING 2021-02-13 22:32:24,586 views 10819 140640061241088 request is processing
WARNING 2021-02-13 22:32:31,262 views 10819 140640061241088 request is processing
WARNING 2021-02-13 22:32:35,916 views 10819 140640061241088 request is processing
ERROR 2021-02-13 22:33:13,615 log 10819 140640061241088 Internal Server Error: /account/register/
Traceback (most recent call last):
  File "/home/krishna/Desktop/ProjectTemplates/djangoBootstrapAuthTemplate/env/lib/python3.6/site-packages/django/core/handlers/exception.py", line 47, in inner
    response = get_response(request)
  File "/home/krishna/Desktop/ProjectTemplates/djangoBootstrapAuthTemplate/env/lib/python3.6/site-packages/django/core/handlers/base.py", line 181, in _get_response
    response = wrapped_callback(request, *callback_args, **callback_kwargs)
  File "/home/krishna/Desktop/ProjectTemplates/djangoBootstrapAuthTemplate/src/account/views.py", line 23, in registration_view
    login(request, account)
  File "/home/krishna/Desktop/ProjectTemplates/djangoBootstrapAuthTemplate/env/lib/python3.6/site-packages/django/contrib/auth/__init__.py", line 126, in login
    request.session[SESSION_KEY] = user._meta.pk.value_to_string(user)
  File "/home/krishna/Desktop/ProjectTemplates/djangoBootstrapAuthTemplate/env/lib/python3.6/site-packages/django/utils/functional.py", line 241, in inner
    return func(self._wrapped, *args)
AttributeError: 'AnonymousUser' object has no attribute '_meta'
ERROR 2021-02-13 22:33:13,615 log 10819 140640061241088 Internal Server Error: /account/register/
Traceback (most recent call last):
  File "/home/krishna/Desktop/ProjectTemplates/djangoBootstrapAuthTemplate/env/lib/python3.6/site-packages/django/core/handlers/exception.py", line 47, in inner
    response = get_response(request)
  File "/home/krishna/Desktop/ProjectTemplates/djangoBootstrapAuthTemplate/env/lib/python3.6/site-packages/django/core/handlers/base.py", line 181, in _get_response
    response = wrapped_callback(request, *callback_args, **callback_kwargs)
  File "/home/krishna/Desktop/ProjectTemplates/djangoBootstrapAuthTemplate/src/account/views.py", line 23, in registration_view
    login(request, account)
  File "/home/krishna/Desktop/ProjectTemplates/djangoBootstrapAuthTemplate/env/lib/python3.6/site-packages/django/contrib/auth/__init__.py", line 126, in login
    request.session[SESSION_KEY] = user._meta.pk.value_to_string(user)
  File "/home/krishna/Desktop/ProjectTemplates/djangoBootstrapAuthTemplate/env/lib/python3.6/site-packages/django/utils/functional.py", line 241, in inner
    return func(self._wrapped, *args)
AttributeError: 'AnonymousUser' object has no attribute '_meta'
ERROR 2021-02-13 22:33:13,678 basehttp 10819 140640061241088 "POST /account/register/ HTTP/1.1" 500 93920
ERROR 2021-02-13 22:33:13,678 basehttp 10819 140640061241088 "POST /account/register/ HTTP/1.1" 500 93920
ERROR 2021-02-13 22:41:30,340 log 15710 140478165432064 Internal Server Error: /account/register/
Traceback (most recent call last):
  File "/home/krishna/Desktop/ProjectTemplates/djangoBootstrapAuthTemplate/env/lib/python3.6/site-packages/django/core/handlers/exception.py", line 47, in inner
    response = get_response(request)
  File "/home/krishna/Desktop/ProjectTemplates/djangoBootstrapAuthTemplate/env/lib/python3.6/site-packages/django/core/handlers/base.py", line 181, in _get_response
    response = wrapped_callback(request, *callback_args, **callback_kwargs)
  File "/home/krishna/Desktop/ProjectTemplates/djangoBootstrapAuthTemplate/src/account/views.py", line 23, in registration_view
    login(request, account)
  File "/home/krishna/Desktop/ProjectTemplates/djangoBootstrapAuthTemplate/env/lib/python3.6/site-packages/django/contrib/auth/__init__.py", line 126, in login
    request.session[SESSION_KEY] = user._meta.pk.value_to_string(user)
  File "/home/krishna/Desktop/ProjectTemplates/djangoBootstrapAuthTemplate/env/lib/python3.6/site-packages/django/utils/functional.py", line 241, in inner
    return func(self._wrapped, *args)
AttributeError: 'AnonymousUser' object has no attribute '_meta'
ERROR 2021-02-13 22:41:30,340 log 15710 140478165432064 Internal Server Error: /account/register/
Traceback (most recent call last):
  File "/home/krishna/Desktop/ProjectTemplates/djangoBootstrapAuthTemplate/env/lib/python3.6/site-packages/django/core/handlers/exception.py", line 47, in inner
    response = get_response(request)
  File "/home/krishna/Desktop/ProjectTemplates/djangoBootstrapAuthTemplate/env/lib/python3.6/site-packages/django/core/handlers/base.py", line 181, in _get_response
    response = wrapped_callback(request, *callback_args, **callback_kwargs)
  File "/home/krishna/Desktop/ProjectTemplates/djangoBootstrapAuthTemplate/src/account/views.py", line 23, in registration_view
    login(request, account)
  File "/home/krishna/Desktop/ProjectTemplates/djangoBootstrapAuthTemplate/env/lib/python3.6/site-packages/django/contrib/auth/__init__.py", line 126, in login
    request.session[SESSION_KEY] = user._meta.pk.value_to_string(user)
  File "/home/krishna/Desktop/ProjectTemplates/djangoBootstrapAuthTemplate/env/lib/python3.6/site-packages/django/utils/functional.py", line 241, in inner
    return func(self._wrapped, *args)
AttributeError: 'AnonymousUser' object has no attribute '_meta'
ERROR 2021-02-13 22:41:30,407 basehttp 15710 140478165432064 "POST /account/register/ HTTP/1.1" 500 93932
ERROR 2021-02-13 22:41:30,407 basehttp 15710 140478165432064 "POST /account/register/ HTTP/1.1" 500 93932
WARNING 2021-02-13 22:45:16,191 views 16182 139923145242368 request is processing
WARNING 2021-02-13 22:47:22,106 views 16182 139923145242368 request is processing
WARNING 2021-02-13 22:49:49,998 views 16182 139923145242368 request is processing
WARNING 2021-02-13 22:50:58,860 views 16182 139923145242368 request is processing
WARNING 2021-02-13 22:52:06,458 views 16182 139923145242368 request is processing
WARNING 2021-02-13 22:53:13,594 views 16182 139923145242368 request is processing
WARNING 2021-02-13 22:53:36,109 views 16182 139923145242368 request is processing
WARNING 2021-02-13 22:57:21,918 views 16182 139923145242368 request is processing
WARNING 2021-02-13 22:58:08,123 views 16182 139923145242368 request is processing
WARNING 2021-02-13 23:03:02,962 views 16182 139923145242368 request is processing
WARNING 2021-02-13 23:04:16,958 views 16182 139923145242368 request is processing
WARNING 2021-02-13 23:04:24,131 views 16182 139923145242368 request is processing
WARNING 2021-02-13 23:04:28,730 views 16182 139923145242368 request is processing
WARNING 2021-02-13 23:04:31,234 views 16182 139923145242368 request is processing
WARNING 2021-02-13 23:04:50,438 views 16182 139923145242368 request is processing
WARNING 2021-02-13 23:08:55,921 views 16182 139923145242368 request is processing
WARNING 2021-02-13 23:20:36,263 views 16182 139923145242368 request is processing
WARNING 2021-02-13 23:20:40,588 views 16182 139923145242368 request is processing
WARNING 2021-02-14 09:02:03,156 views 10875 140112701085440 request is processing
WARNING 2021-02-14 09:02:03,914 log 10875 140112701085440 Not Found: /favicon.ico
WARNING 2021-02-14 09:02:03,914 log 10875 140112701085440 Not Found: /favicon.ico
WARNING 2021-02-14 09:02:03,915 basehttp 10875 140112701085440 "GET /favicon.ico HTTP/1.1" 404 12538
WARNING 2021-02-14 09:02:03,915 basehttp 10875 140112701085440 "GET /favicon.ico HTTP/1.1" 404 12538
WARNING 2021-02-14 09:02:18,028 views 10875 140112701085440 request is processing
WARNING 2021-02-16 11:19:12,727 views 13046 139645916329728 request is processing
WARNING 2021-02-16 11:19:13,401 log 13046 139645916329728 Not Found: /favicon.ico
WARNING 2021-02-16 11:19:13,401 log 13046 139645916329728 Not Found: /favicon.ico
WARNING 2021-02-16 11:19:13,402 basehttp 13046 139645916329728 "GET /favicon.ico HTTP/1.1" 404 12538
WARNING 2021-02-16 11:19:13,402 basehttp 13046 139645916329728 "GET /favicon.ico HTTP/1.1" 404 12538
WARNING 2021-02-16 11:32:05,591 views 13046 139645916329728 request is processing
WARNING 2021-02-16 11:32:41,069 views 13046 139645916329728 request is processing
WARNING 2021-02-16 11:32:49,662 views 13046 139645916329728 request is processing
WARNING 2021-02-16 11:32:51,934 views 13046 139645916329728 request is processing
WARNING 2021-02-16 13:01:19,131 views 19477 139818601080576 request is processing
WARNING 2021-02-16 13:01:53,004 views 19477 139818601080576 request is processing
WARNING 2021-02-16 13:02:11,640 views 19477 139818601080576 request is processing
WARNING 2021-02-16 13:02:38,571 views 19477 139818601080576 request is processing
ERROR 2021-02-16 13:05:17,584 log 19914 140489072953088 Internal Server Error: /account/password_reset/
Traceback (most recent call last):
  File "/home/krishna/Desktop/ProjectTemplates/djangoBootstrapAuthTemplate/env/lib/python3.6/site-packages/django/core/handlers/exception.py", line 47, in inner
    response = get_response(request)
  File "/home/krishna/Desktop/ProjectTemplates/djangoBootstrapAuthTemplate/env/lib/python3.6/site-packages/django/core/handlers/base.py", line 204, in _get_response
    response = response.render()
  File "/home/krishna/Desktop/ProjectTemplates/djangoBootstrapAuthTemplate/env/lib/python3.6/site-packages/django/template/response.py", line 105, in render
    self.content = self.rendered_content
  File "/home/krishna/Desktop/ProjectTemplates/djangoBootstrapAuthTemplate/env/lib/python3.6/site-packages/django/template/response.py", line 81, in rendered_content
    template = self.resolve_template(self.template_name)
  File "/home/krishna/Desktop/ProjectTemplates/djangoBootstrapAuthTemplate/env/lib/python3.6/site-packages/django/template/response.py", line 63, in resolve_template
    return select_template(template, using=self.using)
  File "/home/krishna/Desktop/ProjectTemplates/djangoBootstrapAuthTemplate/env/lib/python3.6/site-packages/django/template/loader.py", line 47, in select_template
    raise TemplateDoesNotExist(', '.join(template_name_list), chain=chain)
django.template.exceptions.TemplateDoesNotExist: account/password_reset_view.html
ERROR 2021-02-16 13:05:17,584 log 19914 140489072953088 Internal Server Error: /account/password_reset/
Traceback (most recent call last):
  File "/home/krishna/Desktop/ProjectTemplates/djangoBootstrapAuthTemplate/env/lib/python3.6/site-packages/django/core/handlers/exception.py", line 47, in inner
    response = get_response(request)
  File "/home/krishna/Desktop/ProjectTemplates/djangoBootstrapAuthTemplate/env/lib/python3.6/site-packages/django/core/handlers/base.py", line 204, in _get_response
    response = response.render()
  File "/home/krishna/Desktop/ProjectTemplates/djangoBootstrapAuthTemplate/env/lib/python3.6/site-packages/django/template/response.py", line 105, in render
    self.content = self.rendered_content
  File "/home/krishna/Desktop/ProjectTemplates/djangoBootstrapAuthTemplate/env/lib/python3.6/site-packages/django/template/response.py", line 81, in rendered_content
    template = self.resolve_template(self.template_name)
  File "/home/krishna/Desktop/ProjectTemplates/djangoBootstrapAuthTemplate/env/lib/python3.6/site-packages/django/template/response.py", line 63, in resolve_template
    return select_template(template, using=self.using)
  File "/home/krishna/Desktop/ProjectTemplates/djangoBootstrapAuthTemplate/env/lib/python3.6/site-packages/django/template/loader.py", line 47, in select_template
    raise TemplateDoesNotExist(', '.join(template_name_list), chain=chain)
django.template.exceptions.TemplateDoesNotExist: account/password_reset_view.html
ERROR 2021-02-16 13:05:17,668 basehttp 19914 140489072953088 "GET /account/password_reset/ HTTP/1.1" 500 98287
ERROR 2021-02-16 13:05:17,668 basehttp 19914 140489072953088 "GET /account/password_reset/ HTTP/1.1" 500 98287
WARNING 2021-02-16 13:07:27,746 views 20034 140421560641280 request is processing
WARNING 2021-02-16 13:17:48,156 views 21200 140129146500864 request is processing
WARNING 2021-02-16 13:17:55,641 views 21200 140129146500864 request is processing
WARNING 2021-02-16 13:18:43,225 views 21200 140129146500864 request is processing
WARNING 2021-02-16 15:04:47,867 log 21200 140129146500864 Not Found: /favicon.ico
WARNING 2021-02-16 15:04:47,867 log 21200 140129146500864 Not Found: /favicon.ico
WARNING 2021-02-16 15:04:47,893 basehttp 21200 140129146500864 "GET /favicon.ico HTTP/1.1" 404 12539
WARNING 2021-02-16 15:04:47,893 basehttp 21200 140129146500864 "GET /favicon.ico HTTP/1.1" 404 12539
WARNING 2021-02-16 15:07:19,209 log 21200 140129146500864 Not Found: /favicon.ico
WARNING 2021-02-16 15:07:19,209 log 21200 140129146500864 Not Found: /favicon.ico
WARNING 2021-02-16 15:07:19,210 basehttp 21200 140129146500864 "GET /favicon.ico HTTP/1.1" 404 12539
WARNING 2021-02-16 15:07:19,210 basehttp 21200 140129146500864 "GET /favicon.ico HTTP/1.1" 404 12539
WARNING 2021-02-16 15:49:46,427 views 31365 139809089976064 request is processing
WARNING 2021-02-16 15:49:49,854 views 31365 139809089976064 request is processing
ERROR 2021-02-16 15:51:07,481 log 31365 139809089976064 Internal Server Error: /account/register/
Traceback (most recent call last):
  File "/home/krishna/Desktop/ProjectTemplates/djangoBootstrapAuthTemplate/env/lib/python3.6/site-packages/django/utils/module_loading.py", line 13, in import_string
    module_path, class_name = dotted_path.rsplit('.', 1)
ValueError: not enough values to unpack (expected 2, got 1)

The above exception was the direct cause of the following exception:

Traceback (most recent call last):
  File "/home/krishna/Desktop/ProjectTemplates/djangoBootstrapAuthTemplate/env/lib/python3.6/site-packages/django/core/handlers/exception.py", line 47, in inner
    response = get_response(request)
  File "/home/krishna/Desktop/ProjectTemplates/djangoBootstrapAuthTemplate/env/lib/python3.6/site-packages/django/core/handlers/base.py", line 181, in _get_response
    response = wrapped_callback(request, *callback_args, **callback_kwargs)
  File "/home/krishna/Desktop/ProjectTemplates/djangoBootstrapAuthTemplate/src/account/views.py", line 48, in registration_view
    email.send()
  File "/home/krishna/Desktop/ProjectTemplates/djangoBootstrapAuthTemplate/env/lib/python3.6/site-packages/django/core/mail/message.py", line 284, in send
    return self.get_connection(fail_silently).send_messages([self])
  File "/home/krishna/Desktop/ProjectTemplates/djangoBootstrapAuthTemplate/env/lib/python3.6/site-packages/django/core/mail/message.py", line 241, in get_connection
    self.connection = get_connection(fail_silently=fail_silently)
  File "/home/krishna/Desktop/ProjectTemplates/djangoBootstrapAuthTemplate/env/lib/python3.6/site-packages/django/core/mail/__init__.py", line 34, in get_connection
    klass = import_string(backend or settings.EMAIL_BACKEND)
  File "/home/krishna/Desktop/ProjectTemplates/djangoBootstrapAuthTemplate/env/lib/python3.6/site-packages/django/utils/module_loading.py", line 15, in import_string
    raise ImportError("%s doesn't look like a module path" % dotted_path) from err
ImportError:  doesn't look like a module path
ERROR 2021-02-16 15:51:07,481 log 31365 139809089976064 Internal Server Error: /account/register/
Traceback (most recent call last):
  File "/home/krishna/Desktop/ProjectTemplates/djangoBootstrapAuthTemplate/env/lib/python3.6/site-packages/django/utils/module_loading.py", line 13, in import_string
    module_path, class_name = dotted_path.rsplit('.', 1)
ValueError: not enough values to unpack (expected 2, got 1)

The above exception was the direct cause of the following exception:

Traceback (most recent call last):
  File "/home/krishna/Desktop/ProjectTemplates/djangoBootstrapAuthTemplate/env/lib/python3.6/site-packages/django/core/handlers/exception.py", line 47, in inner
    response = get_response(request)
  File "/home/krishna/Desktop/ProjectTemplates/djangoBootstrapAuthTemplate/env/lib/python3.6/site-packages/django/core/handlers/base.py", line 181, in _get_response
    response = wrapped_callback(request, *callback_args, **callback_kwargs)
  File "/home/krishna/Desktop/ProjectTemplates/djangoBootstrapAuthTemplate/src/account/views.py", line 48, in registration_view
    email.send()
  File "/home/krishna/Desktop/ProjectTemplates/djangoBootstrapAuthTemplate/env/lib/python3.6/site-packages/django/core/mail/message.py", line 284, in send
    return self.get_connection(fail_silently).send_messages([self])
  File "/home/krishna/Desktop/ProjectTemplates/djangoBootstrapAuthTemplate/env/lib/python3.6/site-packages/django/core/mail/message.py", line 241, in get_connection
    self.connection = get_connection(fail_silently=fail_silently)
  File "/home/krishna/Desktop/ProjectTemplates/djangoBootstrapAuthTemplate/env/lib/python3.6/site-packages/django/core/mail/__init__.py", line 34, in get_connection
    klass = import_string(backend or settings.EMAIL_BACKEND)
  File "/home/krishna/Desktop/ProjectTemplates/djangoBootstrapAuthTemplate/env/lib/python3.6/site-packages/django/utils/module_loading.py", line 15, in import_string
    raise ImportError("%s doesn't look like a module path" % dotted_path) from err
ImportError:  doesn't look like a module path
ERROR 2021-02-16 15:51:07,541 basehttp 31365 139809089976064 "POST /account/register/ HTTP/1.1" 500 106297
ERROR 2021-02-16 15:51:07,541 basehttp 31365 139809089976064 "POST /account/register/ HTTP/1.1" 500 106297
WARNING 2021-02-16 15:56:23,254 views 31956 139680817501952 request is processing
ERROR 2021-02-16 15:58:40,403 log 31956 139680805078784 Internal Server Error: /account/activate/OA/ai670c-87e87f612c04367ca77e661b3b17b1d8/
Traceback (most recent call last):
  File "/home/krishna/Desktop/ProjectTemplates/djangoBootstrapAuthTemplate/env/lib/python3.6/site-packages/django/core/handlers/exception.py", line 47, in inner
    response = get_response(request)
  File "/home/krishna/Desktop/ProjectTemplates/djangoBootstrapAuthTemplate/env/lib/python3.6/site-packages/django/core/handlers/base.py", line 181, in _get_response
    response = wrapped_callback(request, *callback_args, **callback_kwargs)
  File "/home/krishna/Desktop/ProjectTemplates/djangoBootstrapAuthTemplate/src/account/views.py", line 122, in activate
    user = User.objects.get(pk=uid)
  File "/home/krishna/Desktop/ProjectTemplates/djangoBootstrapAuthTemplate/env/lib/python3.6/site-packages/django/db/models/manager.py", line 191, in __get__
    cls._meta.swapped,
AttributeError: Manager isn't available; 'auth.User' has been swapped for 'account.Account'
ERROR 2021-02-16 15:58:40,403 log 31956 139680805078784 Internal Server Error: /account/activate/OA/ai670c-87e87f612c04367ca77e661b3b17b1d8/
Traceback (most recent call last):
  File "/home/krishna/Desktop/ProjectTemplates/djangoBootstrapAuthTemplate/env/lib/python3.6/site-packages/django/core/handlers/exception.py", line 47, in inner
    response = get_response(request)
  File "/home/krishna/Desktop/ProjectTemplates/djangoBootstrapAuthTemplate/env/lib/python3.6/site-packages/django/core/handlers/base.py", line 181, in _get_response
    response = wrapped_callback(request, *callback_args, **callback_kwargs)
  File "/home/krishna/Desktop/ProjectTemplates/djangoBootstrapAuthTemplate/src/account/views.py", line 122, in activate
    user = User.objects.get(pk=uid)
  File "/home/krishna/Desktop/ProjectTemplates/djangoBootstrapAuthTemplate/env/lib/python3.6/site-packages/django/db/models/manager.py", line 191, in __get__
    cls._meta.swapped,
AttributeError: Manager isn't available; 'auth.User' has been swapped for 'account.Account'
ERROR 2021-02-16 15:58:40,455 basehttp 31956 139680805078784 "GET /account/activate/OA/ai670c-87e87f612c04367ca77e661b3b17b1d8/ HTTP/1.1" 500 87714
ERROR 2021-02-16 15:58:40,455 basehttp 31956 139680805078784 "GET /account/activate/OA/ai670c-87e87f612c04367ca77e661b3b17b1d8/ HTTP/1.1" 500 87714
ERROR 2021-02-16 15:59:47,398 log 31956 139680817501952 Internal Server Error: /account/activate/OQ/ai6739-7701f30b58ca5a7e6266523e8f7e1150/
Traceback (most recent call last):
  File "/home/krishna/Desktop/ProjectTemplates/djangoBootstrapAuthTemplate/env/lib/python3.6/site-packages/django/core/handlers/exception.py", line 47, in inner
    response = get_response(request)
  File "/home/krishna/Desktop/ProjectTemplates/djangoBootstrapAuthTemplate/env/lib/python3.6/site-packages/django/core/handlers/base.py", line 181, in _get_response
    response = wrapped_callback(request, *callback_args, **callback_kwargs)
  File "/home/krishna/Desktop/ProjectTemplates/djangoBootstrapAuthTemplate/src/account/views.py", line 122, in activate
    user = User.objects.get(pk=uid)
  File "/home/krishna/Desktop/ProjectTemplates/djangoBootstrapAuthTemplate/env/lib/python3.6/site-packages/django/db/models/manager.py", line 191, in __get__
    cls._meta.swapped,
AttributeError: Manager isn't available; 'auth.User' has been swapped for 'account.Account'
ERROR 2021-02-16 15:59:47,398 log 31956 139680817501952 Internal Server Error: /account/activate/OQ/ai6739-7701f30b58ca5a7e6266523e8f7e1150/
Traceback (most recent call last):
  File "/home/krishna/Desktop/ProjectTemplates/djangoBootstrapAuthTemplate/env/lib/python3.6/site-packages/django/core/handlers/exception.py", line 47, in inner
    response = get_response(request)
  File "/home/krishna/Desktop/ProjectTemplates/djangoBootstrapAuthTemplate/env/lib/python3.6/site-packages/django/core/handlers/base.py", line 181, in _get_response
    response = wrapped_callback(request, *callback_args, **callback_kwargs)
  File "/home/krishna/Desktop/ProjectTemplates/djangoBootstrapAuthTemplate/src/account/views.py", line 122, in activate
    user = User.objects.get(pk=uid)
  File "/home/krishna/Desktop/ProjectTemplates/djangoBootstrapAuthTemplate/env/lib/python3.6/site-packages/django/db/models/manager.py", line 191, in __get__
    cls._meta.swapped,
AttributeError: Manager isn't available; 'auth.User' has been swapped for 'account.Account'
ERROR 2021-02-16 15:59:47,445 basehttp 31956 139680817501952 "GET /account/activate/OQ/ai6739-7701f30b58ca5a7e6266523e8f7e1150/ HTTP/1.1" 500 87714
ERROR 2021-02-16 15:59:47,445 basehttp 31956 139680817501952 "GET /account/activate/OQ/ai6739-7701f30b58ca5a7e6266523e8f7e1150/ HTTP/1.1" 500 87714
WARNING 2021-02-16 16:00:59,127 views 32282 140036884039424 request is processing
WARNING 2021-02-16 16:01:02,029 views 32282 140036884039424 request is processing
WARNING 2021-02-16 16:04:19,822 views 32282 140036884039424 request is processing
WARNING 2021-02-16 16:08:10,160 log 32282 140036884039424 Forbidden (CSRF token missing or incorrect.): /admin/login/
WARNING 2021-02-16 16:08:10,181 basehttp 32282 140036884039424 "POST /admin/login/?next=/admin/account/account/ HTTP/1.1" 403 12468
WARNING 2021-02-16 16:08:10,181 basehttp 32282 140036884039424 "POST /admin/login/?next=/admin/account/account/ HTTP/1.1" 403 12468
WARNING 2021-02-16 16:10:52,498 log 32282 140036884039424 Forbidden (CSRF token missing or incorrect.): /account/login/
WARNING 2021-02-16 16:10:52,527 basehttp 32282 140036884039424 "POST /account/login/ HTTP/1.1" 403 12446
WARNING 2021-02-16 16:10:52,527 basehttp 32282 140036884039424 "POST /account/login/ HTTP/1.1" 403 12446
WARNING 2021-02-16 16:14:02,006 views 32282 140036884039424 request is processing
WARNING 2021-02-16 16:14:04,026 views 32282 140036884039424 request is processing
WARNING 2021-02-16 16:14:07,940 views 32282 140036884039424 request is processing
WARNING 2021-02-16 16:14:18,566 views 32282 140036884039424 request is processing
WARNING 2021-02-16 16:14:29,015 views 32282 140036884039424 request is processing
WARNING 2021-02-16 16:14:39,668 views 32282 140036884039424 request is processing
WARNING 2021-02-16 16:16:03,886 views 32282 140036884039424 request is processing
WARNING 2021-02-16 16:16:17,875 views 32282 140036884039424 request is processing
WARNING 2021-02-16 16:16:25,701 views 32282 140036884039424 request is processing
ERROR 2021-02-16 16:16:52,635 log 32282 140036884039424 Internal Server Error: /account/password_reset/
Traceback (most recent call last):
  File "/home/krishna/Desktop/ProjectTemplates/djangoBootstrapAuthTemplate/env/lib/python3.6/site-packages/django/core/handlers/exception.py", line 47, in inner
    response = get_response(request)
  File "/home/krishna/Desktop/ProjectTemplates/djangoBootstrapAuthTemplate/env/lib/python3.6/site-packages/django/core/handlers/base.py", line 181, in _get_response
    response = wrapped_callback(request, *callback_args, **callback_kwargs)
  File "/home/krishna/Desktop/ProjectTemplates/djangoBootstrapAuthTemplate/env/lib/python3.6/site-packages/django/views/generic/base.py", line 70, in view
    return self.dispatch(request, *args, **kwargs)
  File "/home/krishna/Desktop/ProjectTemplates/djangoBootstrapAuthTemplate/env/lib/python3.6/site-packages/django/utils/decorators.py", line 43, in _wrapper
    return bound_method(*args, **kwargs)
  File "/home/krishna/Desktop/ProjectTemplates/djangoBootstrapAuthTemplate/env/lib/python3.6/site-packages/django/utils/decorators.py", line 130, in _wrapped_view
    response = view_func(request, *args, **kwargs)
  File "/home/krishna/Desktop/ProjectTemplates/djangoBootstrapAuthTemplate/env/lib/python3.6/site-packages/django/contrib/auth/views.py", line 222, in dispatch
    return super().dispatch(*args, **kwargs)
  File "/home/krishna/Desktop/ProjectTemplates/djangoBootstrapAuthTemplate/env/lib/python3.6/site-packages/django/views/generic/base.py", line 98, in dispatch
    return handler(request, *args, **kwargs)
  File "/home/krishna/Desktop/ProjectTemplates/djangoBootstrapAuthTemplate/env/lib/python3.6/site-packages/django/views/generic/edit.py", line 142, in post
    return self.form_valid(form)
  File "/home/krishna/Desktop/ProjectTemplates/djangoBootstrapAuthTemplate/env/lib/python3.6/site-packages/django/contrib/auth/views.py", line 235, in form_valid
    form.save(**opts)
  File "/home/krishna/Desktop/ProjectTemplates/djangoBootstrapAuthTemplate/env/lib/python3.6/site-packages/django/contrib/auth/forms.py", line 325, in save
    user_email, html_email_template_name=html_email_template_name,
  File "/home/krishna/Desktop/ProjectTemplates/djangoBootstrapAuthTemplate/env/lib/python3.6/site-packages/django/contrib/auth/forms.py", line 273, in send_mail
    email_message.send()
  File "/home/krishna/Desktop/ProjectTemplates/djangoBootstrapAuthTemplate/env/lib/python3.6/site-packages/django/core/mail/message.py", line 284, in send
    return self.get_connection(fail_silently).send_messages([self])
  File "/home/krishna/Desktop/ProjectTemplates/djangoBootstrapAuthTemplate/env/lib/python3.6/site-packages/django/core/mail/backends/smtp.py", line 102, in send_messages
    new_conn_created = self.open()
  File "/home/krishna/Desktop/ProjectTemplates/djangoBootstrapAuthTemplate/env/lib/python3.6/site-packages/django/core/mail/backends/smtp.py", line 62, in open
    self.connection = self.connection_class(self.host, self.port, **connection_params)
  File "/usr/lib/python3.6/smtplib.py", line 251, in __init__
    (code, msg) = self.connect(host, port)
  File "/usr/lib/python3.6/smtplib.py", line 336, in connect
    self.sock = self._get_socket(host, port, self.timeout)
  File "/usr/lib/python3.6/smtplib.py", line 307, in _get_socket
    self.source_address)
  File "/usr/lib/python3.6/socket.py", line 704, in create_connection
    for res in getaddrinfo(host, port, 0, SOCK_STREAM):
  File "/usr/lib/python3.6/socket.py", line 745, in getaddrinfo
    for res in _socket.getaddrinfo(host, port, family, type, proto, flags):
socket.gaierror: [Errno -2] Name or service not known
ERROR 2021-02-16 16:16:52,635 log 32282 140036884039424 Internal Server Error: /account/password_reset/
Traceback (most recent call last):
  File "/home/krishna/Desktop/ProjectTemplates/djangoBootstrapAuthTemplate/env/lib/python3.6/site-packages/django/core/handlers/exception.py", line 47, in inner
    response = get_response(request)
  File "/home/krishna/Desktop/ProjectTemplates/djangoBootstrapAuthTemplate/env/lib/python3.6/site-packages/django/core/handlers/base.py", line 181, in _get_response
    response = wrapped_callback(request, *callback_args, **callback_kwargs)
  File "/home/krishna/Desktop/ProjectTemplates/djangoBootstrapAuthTemplate/env/lib/python3.6/site-packages/django/views/generic/base.py", line 70, in view
    return self.dispatch(request, *args, **kwargs)
  File "/home/krishna/Desktop/ProjectTemplates/djangoBootstrapAuthTemplate/env/lib/python3.6/site-packages/django/utils/decorators.py", line 43, in _wrapper
    return bound_method(*args, **kwargs)
  File "/home/krishna/Desktop/ProjectTemplates/djangoBootstrapAuthTemplate/env/lib/python3.6/site-packages/django/utils/decorators.py", line 130, in _wrapped_view
    response = view_func(request, *args, **kwargs)
  File "/home/krishna/Desktop/ProjectTemplates/djangoBootstrapAuthTemplate/env/lib/python3.6/site-packages/django/contrib/auth/views.py", line 222, in dispatch
    return super().dispatch(*args, **kwargs)
  File "/home/krishna/Desktop/ProjectTemplates/djangoBootstrapAuthTemplate/env/lib/python3.6/site-packages/django/views/generic/base.py", line 98, in dispatch
    return handler(request, *args, **kwargs)
  File "/home/krishna/Desktop/ProjectTemplates/djangoBootstrapAuthTemplate/env/lib/python3.6/site-packages/django/views/generic/edit.py", line 142, in post
    return self.form_valid(form)
  File "/home/krishna/Desktop/ProjectTemplates/djangoBootstrapAuthTemplate/env/lib/python3.6/site-packages/django/contrib/auth/views.py", line 235, in form_valid
    form.save(**opts)
  File "/home/krishna/Desktop/ProjectTemplates/djangoBootstrapAuthTemplate/env/lib/python3.6/site-packages/django/contrib/auth/forms.py", line 325, in save
    user_email, html_email_template_name=html_email_template_name,
  File "/home/krishna/Desktop/ProjectTemplates/djangoBootstrapAuthTemplate/env/lib/python3.6/site-packages/django/contrib/auth/forms.py", line 273, in send_mail
    email_message.send()
  File "/home/krishna/Desktop/ProjectTemplates/djangoBootstrapAuthTemplate/env/lib/python3.6/site-packages/django/core/mail/message.py", line 284, in send
    return self.get_connection(fail_silently).send_messages([self])
  File "/home/krishna/Desktop/ProjectTemplates/djangoBootstrapAuthTemplate/env/lib/python3.6/site-packages/django/core/mail/backends/smtp.py", line 102, in send_messages
    new_conn_created = self.open()
  File "/home/krishna/Desktop/ProjectTemplates/djangoBootstrapAuthTemplate/env/lib/python3.6/site-packages/django/core/mail/backends/smtp.py", line 62, in open
    self.connection = self.connection_class(self.host, self.port, **connection_params)
  File "/usr/lib/python3.6/smtplib.py", line 251, in __init__
    (code, msg) = self.connect(host, port)
  File "/usr/lib/python3.6/smtplib.py", line 336, in connect
    self.sock = self._get_socket(host, port, self.timeout)
  File "/usr/lib/python3.6/smtplib.py", line 307, in _get_socket
    self.source_address)
  File "/usr/lib/python3.6/socket.py", line 704, in create_connection
    for res in getaddrinfo(host, port, 0, SOCK_STREAM):
  File "/usr/lib/python3.6/socket.py", line 745, in getaddrinfo
    for res in _socket.getaddrinfo(host, port, family, type, proto, flags):
socket.gaierror: [Errno -2] Name or service not known
ERROR 2021-02-16 16:16:52,699 basehttp 32282 140036884039424 "POST /account/password_reset/ HTTP/1.1" 500 162577
ERROR 2021-02-16 16:16:52,699 basehttp 32282 140036884039424 "POST /account/password_reset/ HTTP/1.1" 500 162577
WARNING 2021-02-16 16:27:17,180 views 1838 140066110764800 request is processing
ERROR 2021-02-16 16:27:40,606 log 1838 140066110764800 Internal Server Error: /account/password_reset/
Traceback (most recent call last):
  File "/home/krishna/Desktop/ProjectTemplates/djangoBootstrapAuthTemplate/env/lib/python3.6/site-packages/django/core/handlers/exception.py", line 47, in inner
    response = get_response(request)
  File "/home/krishna/Desktop/ProjectTemplates/djangoBootstrapAuthTemplate/env/lib/python3.6/site-packages/django/core/handlers/base.py", line 181, in _get_response
    response = wrapped_callback(request, *callback_args, **callback_kwargs)
  File "/home/krishna/Desktop/ProjectTemplates/djangoBootstrapAuthTemplate/env/lib/python3.6/site-packages/django/views/generic/base.py", line 70, in view
    return self.dispatch(request, *args, **kwargs)
  File "/home/krishna/Desktop/ProjectTemplates/djangoBootstrapAuthTemplate/env/lib/python3.6/site-packages/django/utils/decorators.py", line 43, in _wrapper
    return bound_method(*args, **kwargs)
  File "/home/krishna/Desktop/ProjectTemplates/djangoBootstrapAuthTemplate/env/lib/python3.6/site-packages/django/utils/decorators.py", line 130, in _wrapped_view
    response = view_func(request, *args, **kwargs)
  File "/home/krishna/Desktop/ProjectTemplates/djangoBootstrapAuthTemplate/env/lib/python3.6/site-packages/django/contrib/auth/views.py", line 222, in dispatch
    return super().dispatch(*args, **kwargs)
  File "/home/krishna/Desktop/ProjectTemplates/djangoBootstrapAuthTemplate/env/lib/python3.6/site-packages/django/views/generic/base.py", line 98, in dispatch
    return handler(request, *args, **kwargs)
  File "/home/krishna/Desktop/ProjectTemplates/djangoBootstrapAuthTemplate/env/lib/python3.6/site-packages/django/views/generic/edit.py", line 142, in post
    return self.form_valid(form)
  File "/home/krishna/Desktop/ProjectTemplates/djangoBootstrapAuthTemplate/env/lib/python3.6/site-packages/django/contrib/auth/views.py", line 235, in form_valid
    form.save(**opts)
  File "/home/krishna/Desktop/ProjectTemplates/djangoBootstrapAuthTemplate/env/lib/python3.6/site-packages/django/contrib/auth/forms.py", line 325, in save
    user_email, html_email_template_name=html_email_template_name,
  File "/home/krishna/Desktop/ProjectTemplates/djangoBootstrapAuthTemplate/env/lib/python3.6/site-packages/django/contrib/auth/forms.py", line 273, in send_mail
    email_message.send()
  File "/home/krishna/Desktop/ProjectTemplates/djangoBootstrapAuthTemplate/env/lib/python3.6/site-packages/django/core/mail/message.py", line 284, in send
    return self.get_connection(fail_silently).send_messages([self])
  File "/home/krishna/Desktop/ProjectTemplates/djangoBootstrapAuthTemplate/env/lib/python3.6/site-packages/django/core/mail/backends/smtp.py", line 102, in send_messages
    new_conn_created = self.open()
  File "/home/krishna/Desktop/ProjectTemplates/djangoBootstrapAuthTemplate/env/lib/python3.6/site-packages/django/core/mail/backends/smtp.py", line 62, in open
    self.connection = self.connection_class(self.host, self.port, **connection_params)
  File "/usr/lib/python3.6/smtplib.py", line 251, in __init__
    (code, msg) = self.connect(host, port)
  File "/usr/lib/python3.6/smtplib.py", line 336, in connect
    self.sock = self._get_socket(host, port, self.timeout)
  File "/usr/lib/python3.6/smtplib.py", line 307, in _get_socket
    self.source_address)
  File "/usr/lib/python3.6/socket.py", line 704, in create_connection
    for res in getaddrinfo(host, port, 0, SOCK_STREAM):
  File "/usr/lib/python3.6/socket.py", line 745, in getaddrinfo
    for res in _socket.getaddrinfo(host, port, family, type, proto, flags):
socket.gaierror: [Errno -2] Name or service not known
ERROR 2021-02-16 16:27:40,606 log 1838 140066110764800 Internal Server Error: /account/password_reset/
Traceback (most recent call last):
  File "/home/krishna/Desktop/ProjectTemplates/djangoBootstrapAuthTemplate/env/lib/python3.6/site-packages/django/core/handlers/exception.py", line 47, in inner
    response = get_response(request)
  File "/home/krishna/Desktop/ProjectTemplates/djangoBootstrapAuthTemplate/env/lib/python3.6/site-packages/django/core/handlers/base.py", line 181, in _get_response
    response = wrapped_callback(request, *callback_args, **callback_kwargs)
  File "/home/krishna/Desktop/ProjectTemplates/djangoBootstrapAuthTemplate/env/lib/python3.6/site-packages/django/views/generic/base.py", line 70, in view
    return self.dispatch(request, *args, **kwargs)
  File "/home/krishna/Desktop/ProjectTemplates/djangoBootstrapAuthTemplate/env/lib/python3.6/site-packages/django/utils/decorators.py", line 43, in _wrapper
    return bound_method(*args, **kwargs)
  File "/home/krishna/Desktop/ProjectTemplates/djangoBootstrapAuthTemplate/env/lib/python3.6/site-packages/django/utils/decorators.py", line 130, in _wrapped_view
    response = view_func(request, *args, **kwargs)
  File "/home/krishna/Desktop/ProjectTemplates/djangoBootstrapAuthTemplate/env/lib/python3.6/site-packages/django/contrib/auth/views.py", line 222, in dispatch
    return super().dispatch(*args, **kwargs)
  File "/home/krishna/Desktop/ProjectTemplates/djangoBootstrapAuthTemplate/env/lib/python3.6/site-packages/django/views/generic/base.py", line 98, in dispatch
    return handler(request, *args, **kwargs)
  File "/home/krishna/Desktop/ProjectTemplates/djangoBootstrapAuthTemplate/env/lib/python3.6/site-packages/django/views/generic/edit.py", line 142, in post
    return self.form_valid(form)
  File "/home/krishna/Desktop/ProjectTemplates/djangoBootstrapAuthTemplate/env/lib/python3.6/site-packages/django/contrib/auth/views.py", line 235, in form_valid
    form.save(**opts)
  File "/home/krishna/Desktop/ProjectTemplates/djangoBootstrapAuthTemplate/env/lib/python3.6/site-packages/django/contrib/auth/forms.py", line 325, in save
    user_email, html_email_template_name=html_email_template_name,
  File "/home/krishna/Desktop/ProjectTemplates/djangoBootstrapAuthTemplate/env/lib/python3.6/site-packages/django/contrib/auth/forms.py", line 273, in send_mail
    email_message.send()
  File "/home/krishna/Desktop/ProjectTemplates/djangoBootstrapAuthTemplate/env/lib/python3.6/site-packages/django/core/mail/message.py", line 284, in send
    return self.get_connection(fail_silently).send_messages([self])
  File "/home/krishna/Desktop/ProjectTemplates/djangoBootstrapAuthTemplate/env/lib/python3.6/site-packages/django/core/mail/backends/smtp.py", line 102, in send_messages
    new_conn_created = self.open()
  File "/home/krishna/Desktop/ProjectTemplates/djangoBootstrapAuthTemplate/env/lib/python3.6/site-packages/django/core/mail/backends/smtp.py", line 62, in open
    self.connection = self.connection_class(self.host, self.port, **connection_params)
  File "/usr/lib/python3.6/smtplib.py", line 251, in __init__
    (code, msg) = self.connect(host, port)
  File "/usr/lib/python3.6/smtplib.py", line 336, in connect
    self.sock = self._get_socket(host, port, self.timeout)
  File "/usr/lib/python3.6/smtplib.py", line 307, in _get_socket
    self.source_address)
  File "/usr/lib/python3.6/socket.py", line 704, in create_connection
    for res in getaddrinfo(host, port, 0, SOCK_STREAM):
  File "/usr/lib/python3.6/socket.py", line 745, in getaddrinfo
    for res in _socket.getaddrinfo(host, port, family, type, proto, flags):
socket.gaierror: [Errno -2] Name or service not known
ERROR 2021-02-16 16:27:40,645 basehttp 1838 140066110764800 "POST /account/password_reset/ HTTP/1.1" 500 162577
ERROR 2021-02-16 16:27:40,645 basehttp 1838 140066110764800 "POST /account/password_reset/ HTTP/1.1" 500 162577
WARNING 2021-02-16 16:30:15,465 views 2058 140389251958528 request is processing
WARNING 2021-02-16 16:31:38,752 views 2058 140389251958528 request is processing
WARNING 2021-02-16 16:31:41,070 views 2058 140389251958528 request is processing
WARNING 2021-02-16 16:31:56,731 views 2058 140389251958528 request is processing
WARNING 2021-02-16 16:32:00,993 views 2058 140389251958528 request is processing
WARNING 2021-02-16 16:32:18,901 views 2058 140389251958528 request is processing
WARNING 2021-02-16 16:32:43,314 views 2058 140389251958528 request is processing
WARNING 2021-02-16 16:33:34,635 views 2058 140389251958528 request is processing
